Workbook

Sheet Guide
B1: FOREX TRADE JOURNAL - HOW TO USE
B2: A self-calculating journal and analytics suite. Log each trade once; every tab updates.
B4: SET UP (2 minutes)
B5: 1. Settings | C5: Enter your real account balances, default risk %, risk rules and prop-challenge rules. Blue on yellow = editable.
B6: 2. Lists | C6: Rename pairs, setups, emotions, mistake tags and moods; fill blank yellow cells to add your own. Pip size / value drive lot-size checks.
B7: 3. Clear the sample | C7: Journal row 6 is an example so you can see the format. Overwrite it.
B8: TABS
B9: Dashboard | C9: Account-filtered KPI cards, edge finder, prop status and 8 charts. Pick the account in the gold cell top right.
B10: Journal | C10: One row per trade. Blue = you type, grey = automatic. Helper columns on the far right are grouped; click [+] above the column letters to expand.
B11: Daily Journal | C11: Weekday rows from your start date: sleep, mood, plan and review. Trades and P&L fill in; Analytics links mood and sleep to results.
B12: Analytics | C12: 18 breakdown tables (session, pair, setup, hour, hold time, emotion, mistakes, rule checks, accounts, months, mood and sleep).
B13: Weekly Review | C13: 26 weeks of numbers plus three reflection columns.
B14: Goals & Prop | C14: Prop-firm progress bars against your limits, plus monthly goals.
B15: Playbook | C15: Your setups with concise rules and a live Keep / Refine / Review verdict.
B16: Backtest | C16: Log tested trades in R to validate a setup before risking money.
B17: Chart Data | C17: Calculation sheet for the dashboard. Do not edit.
B18: LOGGING A TRADE
B19: Before the trade | C19: Fill Trade Info, Analysis, the 7 confirmations, Planned Entry / Planned Stop, then Entry, Stop, Target, Lot size and Risk %.
B20: After the trade | C20: Enter Exit Price, Exit Time and Fees. Result, outcome, P&L, balance, slippage, hold time and rule check calculate themselves.
B21: Open trades | C21: Leave Exit Price blank. The trade is excluded from statistics until closed.
B22: Rules | C22: Enter trades in date order with no gaps, using dropdowns. Risk % is typed as a percentage (1% or 0.01).
B23: RISK-RULE FLAGS (Journal 'Rule Check')
B24: Oversized | C24: Lot size exceeds the suggested lots (risk $ / stop pips / pip value) by more than the tolerance on Settings.
B25: Overtraded | C25: More trades on the same day (same account) than Max Trades per Day.
B26: Daily loss hit | C26: The day's loss before this trade had already reached Max Daily Loss (% of day-start balance).
B27: Weekly loss hit | C27: The week's loss before this trade had already reached Max Weekly Loss (% of week-start balance).
B28: KEY DEFINITIONS
B29: Win rate | C29: Wins / closed trades. Break-even trades (within the threshold) count as non-wins.
B30: Expectancy (avg R) | C30: Average R per trade. Above 0 means a positive edge over the sample.
B31: Profit factor | C31: Gross profit / gross loss. Above 1 is profitable.
B32: Max drawdown | C32: Largest fall from a balance peak, as a percentage of that peak (for the selected view).
B33: Payoff ratio | C33: Average win (R) divided by average loss (R).
B34: Slippage | C34: (Entry vs Planned Entry) in pips; positive = a worse fill than planned.
B35: ASSUMPTIONS
B36: Currency | C36: Accounts assumed USD (labels say $); the maths works in any currency.
B37: Balances | C37: Account balances (10,000 and 50,000) and all prop-firm limits are placeholders, not your data. Replace them on Settings.
B38: Pip values | C38: Approximate; they move with exchange rates. Confirm with your broker.
B39: Capacity | C39: 500 trades on the Journal. Copy the last row's formulas down to extend, then widen the ranges on other sheets.
B40: Equity chart | C40: Shows 100 trades at a time from the trade # on the Dashboard; the line holds flat after your latest trade.
B41: Educational tool | C41: This workbook records and analyses your trading. It is not financial advice.

Sheet Dashboard
B1: FOREX TRADING PERFORMANCE DASHBOARD | J1: ACCOUNT VIEW > | L1: All Accounts
B2: ="Closed trades in view: "&'Chart Data'!$C$5&" | Journal start: "&TEXT(Settings!$C$7,"dd mmm yyyy")&" | Updates automatically from the Journal tab" -> Closed trades in view: 1 | Journal start: 28 Sep 2026 | Updates automatically from the Journal tab
B4: PERFORMANCE SNAPSHOT
B5: NET P&L ($) | D5: ACCOUNT BALANCE ($) | F5: RETURN % | H5: WIN RATE | J5: PROFIT FACTOR | L5: EXPECTANCY (R)
B6: ='Chart Data'!$C$9 -> 229.5 | D6: ='Chart Data'!$C$18 -> 60229.5 | F6: =IFERROR('Chart Data'!$C$9/'Chart Data'!$C$17,0) -> 0.003825 | H6: =IFERROR('Chart Data'!$C$6/'Chart Data'!$C$5,0) -> 1 | J6: =IF('Chart Data'!$C$11=0,"-",'Chart Data'!$C$10/'Chart Data'!$C$11) -> - | L6: =IFERROR('Chart Data'!$C$12/'Chart Data'!$C$5,0) -> 2.33
B7: ="Profit "&TEXT('Chart Data'!$C$10,"$#,##0")&" | Loss "&TEXT('Chart Data'!$C$11,"$#,##0") -> Profit $230 | Loss $0 | D7: ="Start "&TEXT('Chart Data'!$C$17,"$#,##0") -> Start $60,000 | F7: on starting balance | H7: ="W "&'Chart Data'!$C$6&" / L "&'Chart Data'!$C$7&" / BE "&'Chart Data'!$C$8 -> W 1 / L 0 / BE 0 | J7: above 1.0 = profitable | L7: average R per trade
B9: CLOSED TRADES | D9: MAX DRAWDOWN | F9: AVERAGE WIN (R) | H9: AVERAGE LOSS (R) | J9: PAYOFF RATIO | L9: BEST TRADE (R)
B10: ='Chart Data'!$C$5 -> 1 | D10: ='Chart Data'!$C$19 -> 0 | F10: ='Chart Data'!$C$13 -> 2.33 | H10: ='Chart Data'!$C$14 -> 0 | J10: =IFERROR('Chart Data'!$C$13/ABS('Chart Data'!$C$14),0) -> 0 | L10: ='Chart Data'!$C$15 -> 2.33
B11: in the selected view | D11: peak to trough | F11: winning trades | H11: losing trades | J11: avg win / avg loss | L11: ="Worst "&TEXT('Chart Data'!$C$16,"0.00")&"R" -> Worst 2.33R
B13: DISCIPLINE & RISK CONTROL
B14: PLAN ADHERENCE | D14: RULE BREACHES | F14: A+ SETUP WIN RATE | H14: SWEEP TRADES WIN RATE | J14: LONGEST WIN STREAK | L14: LONGEST LOSS STREAK
B15: =IFERROR('Chart Data'!$C$20/('Chart Data'!$C$20+'Chart Data'!$C$21),0) -> 1 | D15: ='Chart Data'!$C$22 -> 0 | F15: =IF(N(Analytics!$C$87)=0,0,Analytics!$G$87) -> 1 | H15: =IF(N(Analytics!$C$73)=0,0,Analytics!$G$73) -> 1 | J15: ='Chart Data'!$C$24 -> 1 | L15: ='Chart Data'!$C$25 -> 0
B16: ="Yes "&'Chart Data'!$C$20&" / No "&'Chart Data'!$C$21 -> Yes 1 / No 0 | D16: =TEXT(IFERROR('Chart Data'!$C$22/'Chart Data'!$C$5,0),"0%")&" of trades flagged" -> 0% of trades flagged | F16: =N(Analytics!$C$87)&" A+ trades" -> 1 A+ trades | H16: =N(Analytics!$C$73)&" sweep trades" -> 1 sweep trades | J16: trades in a row | L16: ="Avg planned RR "&TEXT('Chart Data'!$C$23,"0.0")&"R" -> Avg planned RR 3.0R
B18: WHERE YOUR EDGE IS (and where it leaks)
B19: BEST SESSION | D19: BEST SETUP | F19: BEST PAIR | H19: BEST WEEKDAY | J19: WEAKEST SETUP | L19: COSTLIEST MISTAKE
B20: ='Chart Data'!$C$28 -> London | D20: ='Chart Data'!$C$30 -> Liquidity Sweep Reversal | F20: ='Chart Data'!$C$32 -> XAUUSD | H20: ='Chart Data'!$C$34 -> Mon | J20: ='Chart Data'!$C$36 -> None yet | L20: ='Chart Data'!$C$38 -> None yet
B21: ="Net "&TEXT('Chart Data'!$C$29,"$#,##0;-$#,##0") -> Net $230 | D21: ="Net "&TEXT('Chart Data'!$C$31,"$#,##0;-$#,##0") -> Net $230 | F21: ="Net "&TEXT('Chart Data'!$C$33,"$#,##0;-$#,##0") -> Net $230 | H21: ="Net "&TEXT('Chart Data'!$C$35,"$#,##0;-$#,##0") -> Net $230 | J21: ="Net "&TEXT('Chart Data'!$C$37,"$#,##0;-$#,##0") -> Net $0 | L21: ="Net "&TEXT('Chart Data'!$C$39,"$#,##0;-$#,##0") -> Net $0
B23: ="PROP CHALLENGE - "&'Goals & Prop'!$C$6&" - "&'Goals & Prop'!$C$22 -> PROP CHALLENGE - Prop Challenge - ON TRACK
B24: PROFIT TARGET PROGRESS | F24: DAILY LOSS LIMIT USED | J24: DRAWDOWN LIMIT USED
B25: ='Goals & Prop'!$C$12 -> 0 | F25: ='Goals & Prop'!$C$16 -> 0 | J25: ='Goals & Prop'!$C$19 -> 0
B26: =REPT("█",ROUND('Goals & Prop'!$C$12*24,0))&REPT("░",24-ROUND('Goals & Prop'!$C$12*24,0)) -> ░░░░░░░░░░░░░░░░░░░░░░░░ | F26: =REPT("█",ROUND('Goals & Prop'!$C$16*24,0))&REPT("░",24-ROUND('Goals & Prop'!$C$16*24,0)) -> ░░░░░░░░░░░░░░░░░░░░░░░░ | J26: =REPT("█",ROUND('Goals & Prop'!$C$19*24,0))&REPT("░",24-ROUND('Goals & Prop'!$C$19*24,0)) -> ░░░░░░░░░░░░░░░░░░░░░░░░
B27: CHARTS | J27: Equity window starts at trade # | L27: 1 | M27: (100 trades shown)

Sheet Journal
A1: FOREX TRADE JOURNAL
A2: Row 6 is a SAMPLE trade - overwrite it. Blue text = you type; grey = auto. Enter trades in date order, no gaps. Leave Exit Price blank for an open trade. Helper columns at the far right are grouped (click [+] to expand).
A4: TRADE INFO | K4: ANALYSIS & CONTEXT | Q4: CONFIRMATIONS (Yes / No) | Z4: EXECUTION (enter) | AI4: RESULTS (auto) | AW4: RISK RULES (auto) | BC4: PSYCHOLOGY & REVIEW | BJ4: HELPERS (auto, grouped)
A5: Trade # | B5: Date | C5: Day | D5: Wk | E5: Account | F5: Session | G5: Entry Time | H5: Exit Time | I5: Pair | J5: Direction | K5: HTF Bias | L5: Setup / Model | M5: Zone Type | N5: Liquidity Sweep? | O5: Sweep Type | P5: Analysis Notes | Q5: Structure Shift (MSS/CHoCH) | R5: Displacement | S5: FVG / Imbalance | T5: Rejection Candle | U5: HTF Aligned | V5: Killzone Timing | W5: News Clear | X5: Confirm. Count | Y5: Setup Grade | Z5: Planned Entry | AA5: Planned Stop | AB5: Entry Price | AC5: Stop Loss | AD5: Take Profit | AE5: Exit Price | AF5: Lot Size | AG5: Risk % | AH5: Fees ($) | AI5: Risk ($) | AJ5: Planned RR | AK5: Result (R) | AL5: Outcome | AM5: Net P&L ($) | AN5: Balance ($) | AO5: Cum. R | AP5: Result (pips) | AQ5: Hold (min) | AR5: Hold Bucket | AS5: Entry Hour | AT5: Slippage (pips, + = worse) | AU5: Stop Moved? | AV5: Suggested Lots | AW5: Balance Before ($) | AX5: Trade # Today | AY5: Day P&L Before ($) | AZ5: Day P&L After ($) | BA5: Week P&L Before ($) | BB5: Rule Check | BC5: Emotion at Entry | BD5: Followed Plan? | BE5: Mistake Tag | BF5: MFE (R) | BG5: MAE (R) | BH5: Screenshot / Chart Link | BI5: Lesson Learned / Journal | BJ5: Account Key | BK5: Acct Start ($) | BL5: Pip Size | BM5: Pip Value ($/lot) | BN5: Acct Peak ($) | BO5: Acct Drawdown % | BP5: In View (1/0) | BQ5: View Trade # | BR5: View Balance ($) | BS5: View Peak ($) | BT5: View Drawdown % | BU5: Win Streak | BV5: Loss Streak
A6: =IF(B6="","",ROW()-5) -> 1 | B6: 46293 | C6: =IF(B6="","",CHOOSE(WEEKDAY(B6,2),"Mon","Tue","Wed","Thu","Fri","Sat","Sun")) -> Mon | D6: =IF(B6="","",WEEKNUM(B6,2)) -> 40 | E6: Main Account | F6: London | G6: 0.35416667 | I6: XAUUSD | J6: Short | K6: Bearish | L6: Liquidity Sweep Reversal | M6: Order Block | N6: Yes | O6: Asia High | P6: Asia high swept at London open into 4H supply. 5m MSS + displacement left an FVG; entered on the FVG retest. | Q6: Yes | R6: Yes | S6: Yes | T6: No | U6: Yes | V6: Yes | W6: Yes | X6: =IF(B6="","",COUNTIF(Q6:W6,"Yes")) -> 6 | Y6: =IF(B6="","",IF(X6>=Settings!$C$16,"A+",IF(X6>=Settings!$C$17,"A",IF(X6>=Settings!$C$18,"B","C")))) -> A+ | AB6: 4120.5 | AC6: 4128 | AD6: 4098 | AE6: 4103 | AG6: 0.01 | AH6: 3.5 | AI6: =IF(B6="","",ROUND(IF(AG6="",Settings!$C$5,AG6)*AW6,2)) -> 100 | AJ6: =IF(OR(B6="",AB6="",AC6="",AD6=""),"",IFERROR(ROUND(ABS(AD6-AB6)/ABS(AB6-AC6),2),"")) -> 3 | AK6: =IF(OR(B6="",AB6="",AC6="",AE6=""),"",IFERROR(ROUND(IF(J6="Short",AB6-AE6,AE6-AB6)/ABS(AB6-AC6),2),"")) -> 2.33 | AL6: =IF(AK6="","",IF(ABS(AK6)<=Settings!$C$6,"BE",IF(AK6>0,"Win","Loss"))) -> Win | AM6: =IF(OR(AK6="",AI6=""),"",ROUND(AK6*AI6-N(AH6),2)) -> 229.5 | AN6: =IF(AM6="","",ROUND(BK6+SUMIFS(AM$6:AM6,BJ$6:BJ6,BJ6),2)) -> 10229.5 | AO6: =IF(AK6="","",ROUND(SUMIFS(AK$6:AK6,BJ$6:BJ6,BJ6),2)) -> 2.33 | AP6: =IF(OR(AK6="",BL6=""),"",IFERROR(ROUND(IF(J6="Short",AB6-AE6,AE6-AB6)/BL6,1),"")) -> 175 | AQ6: =IF(OR(G6="",H6=""),"",ROUND(MOD(H6-G6,1)*1440,0)) | AR6: =IF(AQ6="","",IF(AQ6<15,"Under 15m",IF(AQ6<60,"15-60m",IF(AQ6<240,"1-4 hours","4+ hours")))) | AS6: =IF(G6="","",HOUR(G6)) -> 8 | AT6: =IF(OR(Z6="",AB6="",BL6=""),"",IFERROR(ROUND(IF(J6="Short",Z6-AB6,AB6-Z6)/BL6,1),"")) | AU6: =IF(OR(AA6="",AC6=""),"",IF(AA6=AC6,"No","Yes")) | AV6: =IF(OR(B6="",BL6="",BM6="",AB6="",AC6=""),"",IFERROR(ROUND(AI6/(ABS(AB6-AC6)/BL6*BM6),2),"")) -> 0.13 | AW6: =IF(B6="","",ROUND(BK6+SUMIFS(AM$5:AM5,BJ$5:BJ5,BJ6),2)) -> 10000 | AX6: =IF(B6="","",COUNTIFS(B$6:B6,B6,BJ$6:BJ6,BJ6)) -> 1 | AY6: =IF(B6="","",ROUND(SUMIFS(AM$5:AM5,B$5:B5,B6,BJ$5:BJ5,BJ6),2)) -> 0 | AZ6: =IF(AM6="","",ROUND(AY6+AM6,2)) -> 229.5 | BA6: =IF(B6="","",ROUND(SUMIFS(AM$5:AM5,B$5:B5,">="&(B6-WEEKDAY(B6,2)+1),B$5:B5,"<="&B6,BJ$5:BJ5,BJ6),2)) -> 0 | BB6: =IF(B6="","",IF(AND(AF6<>"",AV6<>"",N(AF6)>N(AV6)*(1+Settings!$C$13)),"Oversized",IF(AX6>Settings!$C$10,"Overtraded",IF(AY6<=-Settings!$C$11*(AW6-AY6),"Daily loss hit",IF(BA6<=-Settings!$C$12*(AW6-BA6),"Weekly loss hit","OK"))))) -> OK | BC6: Calm / Focused | BD6: Yes | BE6: None (Followed Plan) | BF6: 3 | BG6: 0.4 | BH6: (paste your TradingView / screenshot link here) | BI6: Waited for the sweep and the structure shift before entering. Patience paid; no chasing. | BJ6: =IF(B6="","",IF(E6="",Settings!$F$5,E6)) -> Main Account | BK6: =IF(B6="","",IFERROR(INDEX(Settings!$G$5:$G$10,MATCH(BJ6,Settings!$F$5:$F$10,0)),Settings!$G$5)) -> 10000 | BL6: =IF(I6="","",IFERROR(1/(1/INDEX(Lists!$C$6:$C$17,MATCH(I6,Lists!$B$6:$B$17,0))),"")) -> 0.1 | BM6: =IF(I6="","",IFERROR(1/(1/INDEX(Lists!$D$6:$D$17,MATCH(I6,Lists!$B$6:$B$17,0))),"")) -> 10 | BN6: =IF(AN6="","",MAX(BK6,_xlfn.MAXIFS(AN$6:AN6,BJ$6:BJ6,BJ6))) -> 10229.5 | BO6: =IF(AN6="","",(AN6-BN6)/BN6) -> 0 | BP6: =IF(OR(B6="",AL6=""),0,IF(OR(Settings!$C$28="All Accounts",BJ6=Settings!$C$28),1,0)) -> 1 | BQ6: =IF(BP6=1,SUM(BP$6:BP6),"") -> 1 | BR6: =IF(BP6=1,ROUND(Settings!$C$29+SUMIFS(AM$6:AM6,BP$6:BP6,1),2),"") -> 60229.5 | BS6: =IF(BP6=1,MAX(Settings!$C$29,MAX(BR$6:BR6)),"") -> 60229.5 | BT6: =IF(BP6=1,(BR6-BS6)/BS6,"") -> 0 | BU6: =IF(BP6=1,IF(AL6="Win",1+IF(BQ6=1,0,INDEX(BU$5:BU5,MATCH(BQ6-1,BQ$5:BQ5,0))),0),"") -> 1 | BV6: =IF(BP6=1,IF(AL6="Loss",1+IF(BQ6=1,0,INDEX(BV$5:BV5,MATCH(BQ6-1,BQ$5:BQ5,0))),0),"") -> 0
A7: =IF(B7="","",ROW()-5) | C7: =IF(B7="","",CHOOSE(WEEKDAY(B7,2),"Mon","Tue","Wed","Thu","Fri","Sat","Sun")) | D7: =IF(B7="","",WEEKNUM(B7,2)) | X7: =IF(B7="","",COUNTIF(Q7:W7,"Yes")) | Y7: =IF(B7="","",IF(X7>=Settings!$C$16,"A+",IF(X7>=Settings!$C$17,"A",IF(X7>=Settings!$C$18,"B","C")))) | AI7: =IF(B7="","",ROUND(IF(AG7="",Settings!$C$5,AG7)*AW7,2)) | AJ7: =IF(OR(B7="",AB7="",AC7="",AD7=""),"",IFERROR(ROUND(ABS(AD7-AB7)/ABS(AB7-AC7),2),"")) | AK7: =IF(OR(B7="",AB7="",AC7="",AE7=""),"",IFERROR(ROUND(IF(J7="Short",AB7-AE7,AE7-AB7)/ABS(AB7-AC7),2),"")) | AL7: =IF(AK7="","",IF(ABS(AK7)<=Settings!$C$6,"BE",IF(AK7>0,"Win","Loss"))) | AM7: =IF(OR(AK7="",AI7=""),"",ROUND(AK7*AI7-N(AH7),2)) | AN7: =IF(AM7="","",ROUND(BK7+SUMIFS(AM$6:AM7,BJ$6:BJ7,BJ7),2)) | AO7: =IF(AK7="","",ROUND(SUMIFS(AK$6:AK7,BJ$6:BJ7,BJ7),2)) | AP7: =IF(OR(AK7="",BL7=""),"",IFERROR(ROUND(IF(J7="Short",AB7-AE7,AE7-AB7)/BL7,1),"")) | AQ7: =IF(OR(G7="",H7=""),"",ROUND(MOD(H7-G7,1)*1440,0)) | AR7: =IF(AQ7="","",IF(AQ7<15,"Under 15m",IF(AQ7<60,"15-60m",IF(AQ7<240,"1-4 hours","4+ hours")))) | AS7: =IF(G7="","",HOUR(G7)) | AT7: =IF(OR(Z7="",AB7="",BL7=""),"",IFERROR(ROUND(IF(J7="Short",Z7-AB7,AB7-Z7)/BL7,1),"")) | AU7: =IF(OR(AA7="",AC7=""),"",IF(AA7=AC7,"No","Yes")) | AV7: =IF(OR(B7="",BL7="",BM7="",AB7="",AC7=""),"",IFERROR(ROUND(AI7/(ABS(AB7-AC7)/BL7*BM7),2),"")) | AW7: =IF(B7="","",ROUND(BK7+SUMIFS(AM$5:AM6,BJ$5:BJ6,BJ7),2)) | AX7: =IF(B7="","",COUNTIFS(B$6:B7,B7,BJ$6:BJ7,BJ7)) | AY7: =IF(B7="","",ROUND(SUMIFS(AM$5:AM6,B$5:B6,B7,BJ$5:BJ6,BJ7),2)) | AZ7: =IF(AM7="","",ROUND(AY7+AM7,2)) | BA7: =IF(B7="","",ROUND(SUMIFS(AM$5:AM6,B$5:B6,">="&(B7-WEEKDAY(B7,2)+1),B$5:B6,"<="&B7,BJ$5:BJ6,BJ7),2)) | BB7: =IF(B7="","",IF(AND(AF7<>"",AV7<>"",N(AF7)>N(AV7)*(1+Settings!$C$13)),"Oversized",IF(AX7>Settings!$C$10,"Overtraded",IF(AY7<=-Settings!$C$11*(AW7-AY7),"Daily loss hit",IF(BA7<=-Settings!$C$12*(AW7-BA7),"Weekly loss hit","OK"))))) | BJ7: =IF(B7="","",IF(E7="",Settings!$F$5,E7)) | BK7: =IF(B7="","",IFERROR(INDEX(Settings!$G$5:$G$10,MATCH(BJ7,Settings!$F$5:$F$10,0)),Settings!$G$5)) | BL7: =IF(I7="","",IFERROR(1/(1/INDEX(Lists!$C$6:$C$17,MATCH(I7,Lists!$B$6:$B$17,0))),"")) | BM7: =IF(I7="","",IFERROR(1/(1/INDEX(Lists!$D$6:$D$17,MATCH(I7,Lists!$B$6:$B$17,0))),"")) | BN7: =IF(AN7="","",MAX(BK7,_xlfn.MAXIFS(AN$6:AN7,BJ$6:BJ7,BJ7))) | BO7: =IF(AN7="","",(AN7-BN7)/BN7) | BP7: =IF(OR(B7="",AL7=""),0,IF(OR(Settings!$C$28="All Accounts",BJ7=Settings!$C$28),1,0)) -> 0 | BQ7: =IF(BP7=1,SUM(BP$6:BP7),"") | BR7: =IF(BP7=1,ROUND(Settings!$C$29+SUMIFS(AM$6:AM7,BP$6:BP7,1),2),"") | BS7: =IF(BP7=1,MAX(Settings!$C$29,MAX(BR$6:BR7)),"") | BT7: =IF(BP7=1,(BR7-BS7)/BS7,"") | BU7: =IF(BP7=1,IF(AL7="Win",1+IF(BQ7=1,0,INDEX(BU$5:BU6,MATCH(BQ7-1,BQ$5:BQ6,0))),0),"") | BV7: =IF(BP7=1,IF(AL7="Loss",1+IF(BQ7=1,0,INDEX(BV$5:BV6,MATCH(BQ7-1,BQ$5:BQ6,0))),0),"")
A8: =IF(B8="","",ROW()-5) | C8: =IF(B8="","",CHOOSE(WEEKDAY(B8,2),"Mon","Tue","Wed","Thu","Fri","Sat","Sun")) | D8: =IF(B8="","",WEEKNUM(B8,2)) | X8: =IF(B8="","",COUNTIF(Q8:W8,"Yes")) | Y8: =IF(B8="","",IF(X8>=Settings!$C$16,"A+",IF(X8>=Settings!$C$17,"A",IF(X8>=Settings!$C$18,"B","C")))) | AI8: =IF(B8="","",ROUND(IF(AG8="",Settings!$C$5,AG8)*AW8,2)) | AJ8: =IF(OR(B8="",AB8="",AC8="",AD8=""),"",IFERROR(ROUND(ABS(AD8-AB8)/ABS(AB8-AC8),2),"")) | AK8: =IF(OR(B8="",AB8="",AC8="",AE8=""),"",IFERROR(ROUND(IF(J8="Short",AB8-AE8,AE8-AB8)/ABS(AB8-AC8),2),"")) | AL8: =IF(AK8="","",IF(ABS(AK8)<=Settings!$C$6,"BE",IF(AK8>0,"Win","Loss"))) | AM8: =IF(OR(AK8="",AI8=""),"",ROUND(AK8*AI8-N(AH8),2)) | AN8: =IF(AM8="","",ROUND(BK8+SUMIFS(AM$6:AM8,BJ$6:BJ8,BJ8),2)) | AO8: =IF(AK8="","",ROUND(SUMIFS(AK$6:AK8,BJ$6:BJ8,BJ8),2)) | AP8: =IF(OR(AK8="",BL8=""),"",IFERROR(ROUND(IF(J8="Short",AB8-AE8,AE8-AB8)/BL8,1),"")) | AQ8: =IF(OR(G8="",H8=""),"",ROUND(MOD(H8-G8,1)*1440,0)) | AR8: =IF(AQ8="","",IF(AQ8<15,"Under 15m",IF(AQ8<60,"15-60m",IF(AQ8<240,"1-4 hours","4+ hours")))) | AS8: =IF(G8="","",HOUR(G8)) | AT8: =IF(OR(Z8="",AB8="",BL8=""),"",IFERROR(ROUND(IF(J8="Short",Z8-AB8,AB8-Z8)/BL8,1),"")) | AU8: =IF(OR(AA8="",AC8=""),"",IF(AA8=AC8,"No","Yes")) | AV8: =IF(OR(B8="",BL8="",BM8="",AB8="",AC8=""),"",IFERROR(ROUND(AI8/(ABS(AB8-AC8)/BL8*BM8),2),"")) | AW8: =IF(B8="","",ROUND(BK8+SUMIFS(AM$5:AM7,BJ$5:BJ7,BJ8),2)) | AX8: =IF(B8="","",COUNTIFS(B$6:B8,B8,BJ$6:BJ8,BJ8)) | AY8: =IF(B8="","",ROUND(SUMIFS(AM$5:AM7,B$5:B7,B8,BJ$5:BJ7,BJ8),2)) | AZ8: =IF(AM8="","",ROUND(AY8+AM8,2)) | BA8: =IF(B8="","",ROUND(SUMIFS(AM$5:AM7,B$5:B7,">="&(B8-WEEKDAY(B8,2)+1),B$5:B7,"<="&B8,BJ$5:BJ7,BJ8),2)) | BB8: =IF(B8="","",IF(AND(AF8<>"",AV8<>"",N(AF8)>N(AV8)*(1+Settings!$C$13)),"Oversized",IF(AX8>Settings!$C$10,"Overtraded",IF(AY8<=-Settings!$C$11*(AW8-AY8),"Daily loss hit",IF(BA8<=-Settings!$C$12*(AW8-BA8),"Weekly loss hit","OK"))))) | BJ8: =IF(B8="","",IF(E8="",Settings!$F$5,E8)) | BK8: =IF(B8="","",IFERROR(INDEX(Settings!$G$5:$G$10,MATCH(BJ8,Settings!$F$5:$F$10,0)),Settings!$G$5)) | BL8: =IF(I8="","",IFERROR(1/(1/INDEX(Lists!$C$6:$C$17,MATCH(I8,Lists!$B$6:$B$17,0))),"")) | BM8: =IF(I8="","",IFERROR(1/(1/INDEX(Lists!$D$6:$D$17,MATCH(I8,Lists!$B$6:$B$17,0))),"")) | BN8: =IF(AN8="","",MAX(BK8,_xlfn.MAXIFS(AN$6:AN8,BJ$6:BJ8,BJ8))) | BO8: =IF(AN8="","",(AN8-BN8)/BN8) | BP8: =IF(OR(B8="",AL8=""),0,IF(OR(Settings!$C$28="All Accounts",BJ8=Settings!$C$28),1,0)) -> 0 | BQ8: =IF(BP8=1,SUM(BP$6:BP8),"") | BR8: =IF(BP8=1,ROUND(Settings!$C$29+SUMIFS(AM$6:AM8,BP$6:BP8,1),2),"") | BS8: =IF(BP8=1,MAX(Settings!$C$29,MAX(BR$6:BR8)),"") | BT8: =IF(BP8=1,(BR8-BS8)/BS8,"") | BU8: =IF(BP8=1,IF(AL8="Win",1+IF(BQ8=1,0,INDEX(BU$5:BU7,MATCH(BQ8-1,BQ$5:BQ7,0))),0),"") | BV8: =IF(BP8=1,IF(AL8="Loss",1+IF(BQ8=1,0,INDEX(BV$5:BV7,MATCH(BQ8-1,BQ$5:BQ7,0))),0),"")
A9: =IF(B9="","",ROW()-5) | C9: =IF(B9="","",CHOOSE(WEEKDAY(B9,2),"Mon","Tue","Wed","Thu","Fri","Sat","Sun")) | D9: =IF(B9="","",WEEKNUM(B9,2)) | X9: =IF(B9="","",COUNTIF(Q9:W9,"Yes")) | Y9: =IF(B9="","",IF(X9>=Settings!$C$16,"A+",IF(X9>=Settings!$C$17,"A",IF(X9>=Settings!$C$18,"B","C")))) | AI9: =IF(B9="","",ROUND(IF(AG9="",Settings!$C$5,AG9)*AW9,2)) | AJ9: =IF(OR(B9="",AB9="",AC9="",AD9=""),"",IFERROR(ROUND(ABS(AD9-AB9)/ABS(AB9-AC9),2),"")) | AK9: =IF(OR(B9="",AB9="",AC9="",AE9=""),"",IFERROR(ROUND(IF(J9="Short",AB9-AE9,AE9-AB9)/ABS(AB9-AC9),2),"")) | AL9: =IF(AK9="","",IF(ABS(AK9)<=Settings!$C$6,"BE",IF(AK9>0,"Win","Loss"))) | AM9: =IF(OR(AK9="",AI9=""),"",ROUND(AK9*AI9-N(AH9),2)) | AN9: =IF(AM9="","",ROUND(BK9+SUMIFS(AM$6:AM9,BJ$6:BJ9,BJ9),2)) | AO9: =IF(AK9="","",ROUND(SUMIFS(AK$6:AK9,BJ$6:BJ9,BJ9),2)) | AP9: =IF(OR(AK9="",BL9=""),"",IFERROR(ROUND(IF(J9="Short",AB9-AE9,AE9-AB9)/BL9,1),"")) | AQ9: =IF(OR(G9="",H9=""),"",ROUND(MOD(H9-G9,1)*1440,0)) | AR9: =IF(AQ9="","",IF(AQ9<15,"Under 15m",IF(AQ9<60,"15-60m",IF(AQ9<240,"1-4 hours","4+ hours")))) | AS9: =IF(G9="","",HOUR(G9)) | AT9: =IF(OR(Z9="",AB9="",BL9=""),"",IFERROR(ROUND(IF(J9="Short",Z9-AB9,AB9-Z9)/BL9,1),"")) | AU9: =IF(OR(AA9="",AC9=""),"",IF(AA9=AC9,"No","Yes")) | AV9: =IF(OR(B9="",BL9="",BM9="",AB9="",AC9=""),"",IFERROR(ROUND(AI9/(ABS(AB9-AC9)/BL9*BM9),2),"")) | AW9: =IF(B9="","",ROUND(BK9+SUMIFS(AM$5:AM8,BJ$5:BJ8,BJ9),2)) | AX9: =IF(B9="","",COUNTIFS(B$6:B9,B9,BJ$6:BJ9,BJ9)) | AY9: =IF(B9="","",ROUND(SUMIFS(AM$5:AM8,B$5:B8,B9,BJ$5:BJ8,BJ9),2)) | AZ9: =IF(AM9="","",ROUND(AY9+AM9,2)) | BA9: =IF(B9="","",ROUND(SUMIFS(AM$5:AM8,B$5:B8,">="&(B9-WEEKDAY(B9,2)+1),B$5:B8,"<="&B9,BJ$5:BJ8,BJ9),2)) | BB9: =IF(B9="","",IF(AND(AF9<>"",AV9<>"",N(AF9)>N(AV9)*(1+Settings!$C$13)),"Oversized",IF(AX9>Settings!$C$10,"Overtraded",IF(AY9<=-Settings!$C$11*(AW9-AY9),"Daily loss hit",IF(BA9<=-Settings!$C$12*(AW9-BA9),"Weekly loss hit","OK"))))) | BJ9: =IF(B9="","",IF(E9="",Settings!$F$5,E9)) | BK9: =IF(B9="","",IFERROR(INDEX(Settings!$G$5:$G$10,MATCH(BJ9,Settings!$F$5:$F$10,0)),Settings!$G$5)) | BL9: =IF(I9="","",IFERROR(1/(1/INDEX(Lists!$C$6:$C$17,MATCH(I9,Lists!$B$6:$B$17,0))),"")) | BM9: =IF(I9="","",IFERROR(1/(1/INDEX(Lists!$D$6:$D$17,MATCH(I9,Lists!$B$6:$B$17,0))),"")) | BN9: =IF(AN9="","",MAX(BK9,_xlfn.MAXIFS(AN$6:AN9,BJ$6:BJ9,BJ9))) | BO9: =IF(AN9="","",(AN9-BN9)/BN9) | BP9: =IF(OR(B9="",AL9=""),0,IF(OR(Settings!$C$28="All Accounts",BJ9=Settings!$C$28),1,0)) -> 0 | BQ9: =IF(BP9=1,SUM(BP$6:BP9),"") | BR9: =IF(BP9=1,ROUND(Settings!$C$29+SUMIFS(AM$6:AM9,BP$6:BP9,1),2),"") | BS9: =IF(BP9=1,MAX(Settings!$C$29,MAX(BR$6:BR9)),"") | BT9: =IF(BP9=1,(BR9-BS9)/BS9,"") | BU9: =IF(BP9=1,IF(AL9="Win",1+IF(BQ9=1,0,INDEX(BU$5:BU8,MATCH(BQ9-1,BQ$5:BQ8,0))),0),"") | BV9: =IF(BP9=1,IF(AL9="Loss",1+IF(BQ9=1,0,INDEX(BV$5:BV8,MATCH(BQ9-1,BQ$5:BQ8,0))),0),"")
A10: =IF(B10="","",ROW()-5) | C10: =IF(B10="","",CHOOSE(WEEKDAY(B10,2),"Mon","Tue","Wed","Thu","Fri","Sat","Sun")) | D10: =IF(B10="","",WEEKNUM(B10,2)) | X10: =IF(B10="","",COUNTIF(Q10:W10,"Yes")) | Y10: =IF(B10="","",IF(X10>=Settings!$C$16,"A+",IF(X10>=Settings!$C$17,"A",IF(X10>=Settings!$C$18,"B","C")))) | AI10: =IF(B10="","",ROUND(IF(AG10="",Settings!$C$5,AG10)*AW10,2)) | AJ10: =IF(OR(B10="",AB10="",AC10="",AD10=""),"",IFERROR(ROUND(ABS(AD10-AB10)/ABS(AB10-AC10),2),"")) | AK10: =IF(OR(B10="",AB10="",AC10="",AE10=""),"",IFERROR(ROUND(IF(J10="Short",AB10-AE10,AE10-AB10)/ABS(AB10-AC10),2),"")) | AL10: =IF(AK10="","",IF(ABS(AK10)<=Settings!$C$6,"BE",IF(AK10>0,"Win","Loss"))) | AM10: =IF(OR(AK10="",AI10=""),"",ROUND(AK10*AI10-N(AH10),2)) | AN10: =IF(AM10="","",ROUND(BK10+SUMIFS(AM$6:AM10,BJ$6:BJ10,BJ10),2)) | AO10: =IF(AK10="","",ROUND(SUMIFS(AK$6:AK10,BJ$6:BJ10,BJ10),2)) | AP10: =IF(OR(AK10="",BL10=""),"",IFERROR(ROUND(IF(J10="Short",AB10-AE10,AE10-AB10)/BL10,1),"")) | AQ10: =IF(OR(G10="",H10=""),"",ROUND(MOD(H10-G10,1)*1440,0)) | AR10: =IF(AQ10="","",IF(AQ10<15,"Under 15m",IF(AQ10<60,"15-60m",IF(AQ10<240,"1-4 hours","4+ hours")))) | AS10: =IF(G10="","",HOUR(G10)) | AT10: =IF(OR(Z10="",AB10="",BL10=""),"",IFERROR(ROUND(IF(J10="Short",Z10-AB10,AB10-Z10)/BL10,1),"")) | AU10: =IF(OR(AA10="",AC10=""),"",IF(AA10=AC10,"No","Yes")) | AV10: =IF(OR(B10="",BL10="",BM10="",AB10="",AC10=""),"",IFERROR(ROUND(AI10/(ABS(AB10-AC10)/BL10*BM10),2),"")) | AW10: =IF(B10="","",ROUND(BK10+SUMIFS(AM$5:AM9,BJ$5:BJ9,BJ10),2)) | AX10: =IF(B10="","",COUNTIFS(B$6:B10,B10,BJ$6:BJ10,BJ10)) | AY10: =IF(B10="","",ROUND(SUMIFS(AM$5:AM9,B$5:B9,B10,BJ$5:BJ9,BJ10),2)) | AZ10: =IF(AM10="","",ROUND(AY10+AM10,2)) | BA10: =IF(B10="","",ROUND(SUMIFS(AM$5:AM9,B$5:B9,">="&(B10-WEEKDAY(B10,2)+1),B$5:B9,"<="&B10,BJ$5:BJ9,BJ10),2)) | BB10: =IF(B10="","",IF(AND(AF10<>"",AV10<>"",N(AF10)>N(AV10)*(1+Settings!$C$13)),"Oversized",IF(AX10>Settings!$C$10,"Overtraded",IF(AY10<=-Settings!$C$11*(AW10-AY10),"Daily loss hit",IF(BA10<=-Settings!$C$12*(AW10-BA10),"Weekly loss hit","OK"))))) | BJ10: =IF(B10="","",IF(E10="",Settings!$F$5,E10)) | BK10: =IF(B10="","",IFERROR(INDEX(Settings!$G$5:$G$10,MATCH(BJ10,Settings!$F$5:$F$10,0)),Settings!$G$5)) | BL10: =IF(I10="","",IFERROR(1/(1/INDEX(Lists!$C$6:$C$17,MATCH(I10,Lists!$B$6:$B$17,0))),"")) | BM10: =IF(I10="","",IFERROR(1/(1/INDEX(Lists!$D$6:$D$17,MATCH(I10,Lists!$B$6:$B$17,0))),"")) | BN10: =IF(AN10="","",MAX(BK10,_xlfn.MAXIFS(AN$6:AN10,BJ$6:BJ10,BJ10))) | BO10: =IF(AN10="","",(AN10-BN10)/BN10) | BP10: =IF(OR(B10="",AL10=""),0,IF(OR(Settings!$C$28="All Accounts",BJ10=Settings!$C$28),1,0)) -> 0 | BQ10: =IF(BP10=1,SUM(BP$6:BP10),"") | BR10: =IF(BP10=1,ROUND(Settings!$C$29+SUMIFS(AM$6:AM10,BP$6:BP10,1),2),"") | BS10: =IF(BP10=1,MAX(Settings!$C$29,MAX(BR$6:BR10)),"") | BT10: =IF(BP10=1,(BR10-BS10)/BS10,"") | BU10: =IF(BP10=1,IF(AL10="Win",1+IF(BQ10=1,0,INDEX(BU$5:BU9,MATCH(BQ10-1,BQ$5:BQ9,0))),0),"") | BV10: =IF(BP10=1,IF(AL10="Loss",1+IF(BQ10=1,0,INDEX(BV$5:BV9,MATCH(BQ10-1,BQ$5:BQ9,0))),0),"")
A11: =IF(B11="","",ROW()-5) | C11: =IF(B11="","",CHOOSE(WEEKDAY(B11,2),"Mon","Tue","Wed","Thu","Fri","Sat","Sun")) | D11: =IF(B11="","",WEEKNUM(B11,2)) | X11: =IF(B11="","",COUNTIF(Q11:W11,"Yes")) | Y11: =IF(B11="","",IF(X11>=Settings!$C$16,"A+",IF(X11>=Settings!$C$17,"A",IF(X11>=Settings!$C$18,"B","C")))) | AI11: =IF(B11="","",ROUND(IF(AG11="",Settings!$C$5,AG11)*AW11,2)) | AJ11: =IF(OR(B11="",AB11="",AC11="",AD11=""),"",IFERROR(ROUND(ABS(AD11-AB11)/ABS(AB11-AC11),2),"")) | AK11: =IF(OR(B11="",AB11="",AC11="",AE11=""),"",IFERROR(ROUND(IF(J11="Short",AB11-AE11,AE11-AB11)/ABS(AB11-AC11),2),"")) | AL11: =IF(AK11="","",IF(ABS(AK11)<=Settings!$C$6,"BE",IF(AK11>0,"Win","Loss"))) | AM11: =IF(OR(AK11="",AI11=""),"",ROUND(AK11*AI11-N(AH11),2)) | AN11: =IF(AM11="","",ROUND(BK11+SUMIFS(AM$6:AM11,BJ$6:BJ11,BJ11),2)) | AO11: =IF(AK11="","",ROUND(SUMIFS(AK$6:AK11,BJ$6:BJ11,BJ11),2)) | AP11: =IF(OR(AK11="",BL11=""),"",IFERROR(ROUND(IF(J11="Short",AB11-AE11,AE11-AB11)/BL11,1),"")) | AQ11: =IF(OR(G11="",H11=""),"",ROUND(MOD(H11-G11,1)*1440,0)) | AR11: =IF(AQ11="","",IF(AQ11<15,"Under 15m",IF(AQ11<60,"15-60m",IF(AQ11<240,"1-4 hours","4+ hours")))) | AS11: =IF(G11="","",HOUR(G11)) | AT11: =IF(OR(Z11="",AB11="",BL11=""),"",IFERROR(ROUND(IF(J11="Short",Z11-AB11,AB11-Z11)/BL11,1),"")) | AU11: =IF(OR(AA11="",AC11=""),"",IF(AA11=AC11,"No","Yes")) | AV11: =IF(OR(B11="",BL11="",BM11="",AB11="",AC11=""),"",IFERROR(ROUND(AI11/(ABS(AB11-AC11)/BL11*BM11),2),"")) | AW11: =IF(B11="","",ROUND(BK11+SUMIFS(AM$5:AM10,BJ$5:BJ10,BJ11),2)) | AX11: =IF(B11="","",COUNTIFS(B$6:B11,B11,BJ$6:BJ11,BJ11)) | AY11: =IF(B11="","",ROUND(SUMIFS(AM$5:AM10,B$5:B10,B11,BJ$5:BJ10,BJ11),2)) | AZ11: =IF(AM11="","",ROUND(AY11+AM11,2)) | BA11: =IF(B11="","",ROUND(SUMIFS(AM$5:AM10,B$5:B10,">="&(B11-WEEKDAY(B11,2)+1),B$5:B10,"<="&B11,BJ$5:BJ10,BJ11),2)) | BB11: =IF(B11="","",IF(AND(AF11<>"",AV11<>"",N(AF11)>N(AV11)*(1+Settings!$C$13)),"Oversized",IF(AX11>Settings!$C$10,"Overtraded",IF(AY11<=-Settings!$C$11*(AW11-AY11),"Daily loss hit",IF(BA11<=-Settings!$C$12*(AW11-BA11),"Weekly loss hit","OK"))))) | BJ11: =IF(B11="","",IF(E11="",Settings!$F$5,E11)) | BK11: =IF(B11="","",IFERROR(INDEX(Settings!$G$5:$G$10,MATCH(BJ11,Settings!$F$5:$F$10,0)),Settings!$G$5)) | BL11: =IF(I11="","",IFERROR(1/(1/INDEX(Lists!$C$6:$C$17,MATCH(I11,Lists!$B$6:$B$17,0))),"")) | BM11: =IF(I11="","",IFERROR(1/(1/INDEX(Lists!$D$6:$D$17,MATCH(I11,Lists!$B$6:$B$17,0))),"")) | BN11: =IF(AN11="","",MAX(BK11,_xlfn.MAXIFS(AN$6:AN11,BJ$6:BJ11,BJ11))) | BO11: =IF(AN11="","",(AN11-BN11)/BN11) | BP11: =IF(OR(B11="",AL11=""),0,IF(OR(Settings!$C$28="All Accounts",BJ11=Settings!$C$28),1,0)) -> 0 | BQ11: =IF(BP11=1,SUM(BP$6:BP11),"") | BR11: =IF(BP11=1,ROUND(Settings!$C$29+SUMIFS(AM$6:AM11,BP$6:BP11,1),2),"") | BS11: =IF(BP11=1,MAX(Settings!$C$29,MAX(BR$6:BR11)),"") | BT11: =IF(BP11=1,(BR11-BS11)/BS11,"") | BU11: =IF(BP11=1,IF(AL11="Win",1+IF(BQ11=1,0,INDEX(BU$5:BU10,MATCH(BQ11-1,BQ$5:BQ10,0))),0),"") | BV11: =IF(BP11=1,IF(AL11="Loss",1+IF(BQ11=1,0,INDEX(BV$5:BV10,MATCH(BQ11-1,BQ$5:BQ10,0))),0),"")
A12: =IF(B12="","",ROW()-5) | C12: =IF(B12="","",CHOOSE(WEEKDAY(B12,2),"Mon","Tue","Wed","Thu","Fri","Sat","Sun")) | D12: =IF(B12="","",WEEKNUM(B12,2)) | X12: =IF(B12="","",COUNTIF(Q12:W12,"Yes")) | Y12: =IF(B12="","",IF(X12>=Settings!$C$16,"A+",IF(X12>=Settings!$C$17,"A",IF(X12>=Settings!$C$18,"B","C")))) | AI12: =IF(B12="","",ROUND(IF(AG12="",Settings!$C$5,AG12)*AW12,2)) | AJ12: =IF(OR(B12="",AB12="",AC12="",AD12=""),"",IFERROR(ROUND(ABS(AD12-AB12)/ABS(AB12-AC12),2),"")) | AK12: =IF(OR(B12="",AB12="",AC12="",AE12=""),"",IFERROR(ROUND(IF(J12="Short",AB12-AE12,AE12-AB12)/ABS(AB12-AC12),2),"")) | AL12: =IF(AK12="","",IF(ABS(AK12)<=Settings!$C$6,"BE",IF(AK12>0,"Win","Loss"))) | AM12: =IF(OR(AK12="",AI12=""),"",ROUND(AK12*AI12-N(AH12),2)) | AN12: =IF(AM12="","",ROUND(BK12+SUMIFS(AM$6:AM12,BJ$6:BJ12,BJ12),2)) | AO12: =IF(AK12="","",ROUND(SUMIFS(AK$6:AK12,BJ$6:BJ12,BJ12),2)) | AP12: =IF(OR(AK12="",BL12=""),"",IFERROR(ROUND(IF(J12="Short",AB12-AE12,AE12-AB12)/BL12,1),"")) | AQ12: =IF(OR(G12="",H12=""),"",ROUND(MOD(H12-G12,1)*1440,0)) | AR12: =IF(AQ12="","",IF(AQ12<15,"Under 15m",IF(AQ12<60,"15-60m",IF(AQ12<240,"1-4 hours","4+ hours")))) | AS12: =IF(G12="","",HOUR(G12)) | AT12: =IF(OR(Z12="",AB12="",BL12=""),"",IFERROR(ROUND(IF(J12="Short",Z12-AB12,AB12-Z12)/BL12,1),"")) | AU12: =IF(OR(AA12="",AC12=""),"",IF(AA12=AC12,"No","Yes")) | AV12: =IF(OR(B12="",BL12="",BM12="",AB12="",AC12=""),"",IFERROR(ROUND(AI12/(ABS(AB12-AC12)/BL12*BM12),2),"")) | AW12: =IF(B12="","",ROUND(BK12+SUMIFS(AM$5:AM11,BJ$5:BJ11,BJ12),2)) | AX12: =IF(B12="","",COUNTIFS(B$6:B12,B12,BJ$6:BJ12,BJ12)) | AY12: =IF(B12="","",ROUND(SUMIFS(AM$5:AM11,B$5:B11,B12,BJ$5:BJ11,BJ12),2)) | AZ12: =IF(AM12="","",ROUND(AY12+AM12,2)) | BA12: =IF(B12="","",ROUND(SUMIFS(AM$5:AM11,B$5:B11,">="&(B12-WEEKDAY(B12,2)+1),B$5:B11,"<="&B12,BJ$5:BJ11,BJ12),2)) | BB12: =IF(B12="","",IF(AND(AF12<>"",AV12<>"",N(AF12)>N(AV12)*(1+Settings!$C$13)),"Oversized",IF(AX12>Settings!$C$10,"Overtraded",IF(AY12<=-Settings!$C$11*(AW12-AY12),"Daily loss hit",IF(BA12<=-Settings!$C$12*(AW12-BA12),"Weekly loss hit","OK"))))) | BJ12: =IF(B12="","",IF(E12="",Settings!$F$5,E12)) | BK12: =IF(B12="","",IFERROR(INDEX(Settings!$G$5:$G$10,MATCH(BJ12,Settings!$F$5:$F$10,0)),Settings!$G$5)) | BL12: =IF(I12="","",IFERROR(1/(1/INDEX(Lists!$C$6:$C$17,MATCH(I12,Lists!$B$6:$B$17,0))),"")) | BM12: =IF(I12="","",IFERROR(1/(1/INDEX(Lists!$D$6:$D$17,MATCH(I12,Lists!$B$6:$B$17,0))),"")) | BN12: =IF(AN12="","",MAX(BK12,_xlfn.MAXIFS(AN$6:AN12,BJ$6:BJ12,BJ12))) | BO12: =IF(AN12="","",(AN12-BN12)/BN12) | BP12: =IF(OR(B12="",AL12=""),0,IF(OR(Settings!$C$28="All Accounts",BJ12=Settings!$C$28),1,0)) -> 0 | BQ12: =IF(BP12=1,SUM(BP$6:BP12),"") | BR12: =IF(BP12=1,ROUND(Settings!$C$29+SUMIFS(AM$6:AM12,BP$6:BP12,1),2),"") | BS12: =IF(BP12=1,MAX(Settings!$C$29,MAX(BR$6:BR12)),"") | BT12: =IF(BP12=1,(BR12-BS12)/BS12,"") | BU12: =IF(BP12=1,IF(AL12="Win",1+IF(BQ12=1,0,INDEX(BU$5:BU11,MATCH(BQ12-1,BQ$5:BQ11,0))),0),"") | BV12: =IF(BP12=1,IF(AL12="Loss",1+IF(BQ12=1,0,INDEX(BV$5:BV11,MATCH(BQ12-1,BQ$5:BQ11,0))),0),"")
A13: =IF(B13="","",ROW()-5) | C13: =IF(B13="","",CHOOSE(WEEKDAY(B13,2),"Mon","Tue","Wed","Thu","Fri","Sat","Sun")) | D13: =IF(B13="","",WEEKNUM(B13,2)) | X13: =IF(B13="","",COUNTIF(Q13:W13,"Yes")) | Y13: =IF(B13="","",IF(X13>=Settings!$C$16,"A+",IF(X13>=Settings!$C$17,"A",IF(X13>=Settings!$C$18,"B","C")))) | AI13: =IF(B13="","",ROUND(IF(AG13="",Settings!$C$5,AG13)*AW13,2)) | AJ13: =IF(OR(B13="",AB13="",AC13="",AD13=""),"",IFERROR(ROUND(ABS(AD13-AB13)/ABS(AB13-AC13),2),"")) | AK13: =IF(OR(B13="",AB13="",AC13="",AE13=""),"",IFERROR(ROUND(IF(J13="Short",AB13-AE13,AE13-AB13)/ABS(AB13-AC13),2),"")) | AL13: =IF(AK13="","",IF(ABS(AK13)<=Settings!$C$6,"BE",IF(AK13>0,"Win","Loss"))) | AM13: =IF(OR(AK13="",AI13=""),"",ROUND(AK13*AI13-N(AH13),2)) | AN13: =IF(AM13="","",ROUND(BK13+SUMIFS(AM$6:AM13,BJ$6:BJ13,BJ13),2)) | AO13: =IF(AK13="","",ROUND(SUMIFS(AK$6:AK13,BJ$6:BJ13,BJ13),2)) | AP13: =IF(OR(AK13="",BL13=""),"",IFERROR(ROUND(IF(J13="Short",AB13-AE13,AE13-AB13)/BL13,1),"")) | AQ13: =IF(OR(G13="",H13=""),"",ROUND(MOD(H13-G13,1)*1440,0)) | AR13: =IF(AQ13="","",IF(AQ13<15,"Under 15m",IF(AQ13<60,"15-60m",IF(AQ13<240,"1-4 hours","4+ hours")))) | AS13: =IF(G13="","",HOUR(G13)) | AT13: =IF(OR(Z13="",AB13="",BL13=""),"",IFERROR(ROUND(IF(J13="Short",Z13-AB13,AB13-Z13)/BL13,1),"")) | AU13: =IF(OR(AA13="",AC13=""),"",IF(AA13=AC13,"No","Yes")) | AV13: =IF(OR(B13="",BL13="",BM13="",AB13="",AC13=""),"",IFERROR(ROUND(AI13/(ABS(AB13-AC13)/BL13*BM13),2),"")) | AW13: =IF(B13="","",ROUND(BK13+SUMIFS(AM$5:AM12,BJ$5:BJ12,BJ13),2)) | AX13: =IF(B13="","",COUNTIFS(B$6:B13,B13,BJ$6:BJ13,BJ13)) | AY13: =IF(B13="","",ROUND(SUMIFS(AM$5:AM12,B$5:B12,B13,BJ$5:BJ12,BJ13),2)) | AZ13: =IF(AM13="","",ROUND(AY13+AM13,2)) | BA13: =IF(B13="","",ROUND(SUMIFS(AM$5:AM12,B$5:B12,">="&(B13-WEEKDAY(B13,2)+1),B$5:B12,"<="&B13,BJ$5:BJ12,BJ13),2)) | BB13: =IF(B13="","",IF(AND(AF13<>"",AV13<>"",N(AF13)>N(AV13)*(1+Settings!$C$13)),"Oversized",IF(AX13>Settings!$C$10,"Overtraded",IF(AY13<=-Settings!$C$11*(AW13-AY13),"Daily loss hit",IF(BA13<=-Settings!$C$12*(AW13-BA13),"Weekly loss hit","OK"))))) | BJ13: =IF(B13="","",IF(E13="",Settings!$F$5,E13)) | BK13: =IF(B13="","",IFERROR(INDEX(Settings!$G$5:$G$10,MATCH(BJ13,Settings!$F$5:$F$10,0)),Settings!$G$5)) | BL13: =IF(I13="","",IFERROR(1/(1/INDEX(Lists!$C$6:$C$17,MATCH(I13,Lists!$B$6:$B$17,0))),"")) | BM13: =IF(I13="","",IFERROR(1/(1/INDEX(Lists!$D$6:$D$17,MATCH(I13,Lists!$B$6:$B$17,0))),"")) | BN13: =IF(AN13="","",MAX(BK13,_xlfn.MAXIFS(AN$6:AN13,BJ$6:BJ13,BJ13))) | BO13: =IF(AN13="","",(AN13-BN13)/BN13) | BP13: =IF(OR(B13="",AL13=""),0,IF(OR(Settings!$C$28="All Accounts",BJ13=Settings!$C$28),1,0)) -> 0 | BQ13: =IF(BP13=1,SUM(BP$6:BP13),"") | BR13: =IF(BP13=1,ROUND(Settings!$C$29+SUMIFS(AM$6:AM13,BP$6:BP13,1),2),"") | BS13: =IF(BP13=1,MAX(Settings!$C$29,MAX(BR$6:BR13)),"") | BT13: =IF(BP13=1,(BR13-BS13)/BS13,"") | BU13: =IF(BP13=1,IF(AL13="Win",1+IF(BQ13=1,0,INDEX(BU$5:BU12,MATCH(BQ13-1,BQ$5:BQ12,0))),0),"") | BV13: =IF(BP13=1,IF(AL13="Loss",1+IF(BQ13=1,0,INDEX(BV$5:BV12,MATCH(BQ13-1,BQ$5:BQ12,0))),0),"")
A14: =IF(B14="","",ROW()-5) | C14: =IF(B14="","",CHOOSE(WEEKDAY(B14,2),"Mon","Tue","Wed","Thu","Fri","Sat","Sun")) | D14: =IF(B14="","",WEEKNUM(B14,2)) | X14: =IF(B14="","",COUNTIF(Q14:W14,"Yes")) | Y14: =IF(B14="","",IF(X14>=Settings!$C$16,"A+",IF(X14>=Settings!$C$17,"A",IF(X14>=Settings!$C$18,"B","C")))) | AI14: =IF(B14="","",ROUND(IF(AG14="",Settings!$C$5,AG14)*AW14,2)) | AJ14: =IF(OR(B14="",AB14="",AC14="",AD14=""),"",IFERROR(ROUND(ABS(AD14-AB14)/ABS(AB14-AC14),2),"")) | AK14: =IF(OR(B14="",AB14="",AC14="",AE14=""),"",IFERROR(ROUND(IF(J14="Short",AB14-AE14,AE14-AB14)/ABS(AB14-AC14),2),"")) | AL14: =IF(AK14="","",IF(ABS(AK14)<=Settings!$C$6,"BE",IF(AK14>0,"Win","Loss"))) | AM14: =IF(OR(AK14="",AI14=""),"",ROUND(AK14*AI14-N(AH14),2)) | AN14: =IF(AM14="","",ROUND(BK14+SUMIFS(AM$6:AM14,BJ$6:BJ14,BJ14),2)) | AO14: =IF(AK14="","",ROUND(SUMIFS(AK$6:AK14,BJ$6:BJ14,BJ14),2)) | AP14: =IF(OR(AK14="",BL14=""),"",IFERROR(ROUND(IF(J14="Short",AB14-AE14,AE14-AB14)/BL14,1),"")) | AQ14: =IF(OR(G14="",H14=""),"",ROUND(MOD(H14-G14,1)*1440,0)) | AR14: =IF(AQ14="","",IF(AQ14<15,"Under 15m",IF(AQ14<60,"15-60m",IF(AQ14<240,"1-4 hours","4+ hours")))) | AS14: =IF(G14="","",HOUR(G14)) | AT14: =IF(OR(Z14="",AB14="",BL14=""),"",IFERROR(ROUND(IF(J14="Short",Z14-AB14,AB14-Z14)/BL14,1),"")) | AU14: =IF(OR(AA14="",AC14=""),"",IF(AA14=AC14,"No","Yes")) | AV14: =IF(OR(B14="",BL14="",BM14="",AB14="",AC14=""),"",IFERROR(ROUND(AI14/(ABS(AB14-AC14)/BL14*BM14),2),"")) | AW14: =IF(B14="","",ROUND(BK14+SUMIFS(AM$5:AM13,BJ$5:BJ13,BJ14),2)) | AX14: =IF(B14="","",COUNTIFS(B$6:B14,B14,BJ$6:BJ14,BJ14)) | AY14: =IF(B14="","",ROUND(SUMIFS(AM$5:AM13,B$5:B13,B14,BJ$5:BJ13,BJ14),2)) | AZ14: =IF(AM14="","",ROUND(AY14+AM14,2)) | BA14: =IF(B14="","",ROUND(SUMIFS(AM$5:AM13,B$5:B13,">="&(B14-WEEKDAY(B14,2)+1),B$5:B13,"<="&B14,BJ$5:BJ13,BJ14),2)) | BB14: =IF(B14="","",IF(AND(AF14<>"",AV14<>"",N(AF14)>N(AV14)*(1+Settings!$C$13)),"Oversized",IF(AX14>Settings!$C$10,"Overtraded",IF(AY14<=-Settings!$C$11*(AW14-AY14),"Daily loss hit",IF(BA14<=-Settings!$C$12*(AW14-BA14),"Weekly loss hit","OK"))))) | BJ14: =IF(B14="","",IF(E14="",Settings!$F$5,E14)) | BK14: =IF(B14="","",IFERROR(INDEX(Settings!$G$5:$G$10,MATCH(BJ14,Settings!$F$5:$F$10,0)),Settings!$G$5)) | BL14: =IF(I14="","",IFERROR(1/(1/INDEX(Lists!$C$6:$C$17,MATCH(I14,Lists!$B$6:$B$17,0))),"")) | BM14: =IF(I14="","",IFERROR(1/(1/INDEX(Lists!$D$6:$D$17,MATCH(I14,Lists!$B$6:$B$17,0))),"")) | BN14: =IF(AN14="","",MAX(BK14,_xlfn.MAXIFS(AN$6:AN14,BJ$6:BJ14,BJ14))) | BO14: =IF(AN14="","",(AN14-BN14)/BN14) | BP14: =IF(OR(B14="",AL14=""),0,IF(OR(Settings!$C$28="All Accounts",BJ14=Settings!$C$28),1,0)) -> 0 | BQ14: =IF(BP14=1,SUM(BP$6:BP14),"") | BR14: =IF(BP14=1,ROUND(Settings!$C$29+SUMIFS(AM$6:AM14,BP$6:BP14,1),2),"") | BS14: =IF(BP14=1,MAX(Settings!$C$29,MAX(BR$6:BR14)),"") | BT14: =IF(BP14=1,(BR14-BS14)/BS14,"") | BU14: =IF(BP14=1,IF(AL14="Win",1+IF(BQ14=1,0,INDEX(BU$5:BU13,MATCH(BQ14-1,BQ$5:BQ13,0))),0),"") | BV14: =IF(BP14=1,IF(AL14="Loss",1+IF(BQ14=1,0,INDEX(BV$5:BV13,MATCH(BQ14-1,BQ$5:BQ13,0))),0),"")
A15: =IF(B15="","",ROW()-5) | C15: =IF(B15="","",CHOOSE(WEEKDAY(B15,2),"Mon","Tue","Wed","Thu","Fri","Sat","Sun")) | D15: =IF(B15="","",WEEKNUM(B15,2)) | X15: =IF(B15="","",COUNTIF(Q15:W15,"Yes")) | Y15: =IF(B15="","",IF(X15>=Settings!$C$16,"A+",IF(X15>=Settings!$C$17,"A",IF(X15>=Settings!$C$18,"B","C")))) | AI15: =IF(B15="","",ROUND(IF(AG15="",Settings!$C$5,AG15)*AW15,2)) | AJ15: =IF(OR(B15="",AB15="",AC15="",AD15=""),"",IFERROR(ROUND(ABS(AD15-AB15)/ABS(AB15-AC15),2),"")) | AK15: =IF(OR(B15="",AB15="",AC15="",AE15=""),"",IFERROR(ROUND(IF(J15="Short",AB15-AE15,AE15-AB15)/ABS(AB15-AC15),2),"")) | AL15: =IF(AK15="","",IF(ABS(AK15)<=Settings!$C$6,"BE",IF(AK15>0,"Win","Loss"))) | AM15: =IF(OR(AK15="",AI15=""),"",ROUND(AK15*AI15-N(AH15),2)) | AN15: =IF(AM15="","",ROUND(BK15+SUMIFS(AM$6:AM15,BJ$6:BJ15,BJ15),2)) | AO15: =IF(AK15="","",ROUND(SUMIFS(AK$6:AK15,BJ$6:BJ15,BJ15),2)) | AP15: =IF(OR(AK15="",BL15=""),"",IFERROR(ROUND(IF(J15="Short",AB15-AE15,AE15-AB15)/BL15,1),"")) | AQ15: =IF(OR(G15="",H15=""),"",ROUND(MOD(H15-G15,1)*1440,0)) | AR15: =IF(AQ15="","",IF(AQ15<15,"Under 15m",IF(AQ15<60,"15-60m",IF(AQ15<240,"1-4 hours","4+ hours")))) | AS15: =IF(G15="","",HOUR(G15)) | AT15: =IF(OR(Z15="",AB15="",BL15=""),"",IFERROR(ROUND(IF(J15="Short",Z15-AB15,AB15-Z15)/BL15,1),"")) | AU15: =IF(OR(AA15="",AC15=""),"",IF(AA15=AC15,"No","Yes")) | AV15: =IF(OR(B15="",BL15="",BM15="",AB15="",AC15=""),"",IFERROR(ROUND(AI15/(ABS(AB15-AC15)/BL15*BM15),2),"")) | AW15: =IF(B15="","",ROUND(BK15+SUMIFS(AM$5:AM14,BJ$5:BJ14,BJ15),2)) | AX15: =IF(B15="","",COUNTIFS(B$6:B15,B15,BJ$6:BJ15,BJ15)) | AY15: =IF(B15="","",ROUND(SUMIFS(AM$5:AM14,B$5:B14,B15,BJ$5:BJ14,BJ15),2)) | AZ15: =IF(AM15="","",ROUND(AY15+AM15,2)) | BA15: =IF(B15="","",ROUND(SUMIFS(AM$5:AM14,B$5:B14,">="&(B15-WEEKDAY(B15,2)+1),B$5:B14,"<="&B15,BJ$5:BJ14,BJ15),2)) | BB15: =IF(B15="","",IF(AND(AF15<>"",AV15<>"",N(AF15)>N(AV15)*(1+Settings!$C$13)),"Oversized",IF(AX15>Settings!$C$10,"Overtraded",IF(AY15<=-Settings!$C$11*(AW15-AY15),"Daily loss hit",IF(BA15<=-Settings!$C$12*(AW15-BA15),"Weekly loss hit","OK"))))) | BJ15: =IF(B15="","",IF(E15="",Settings!$F$5,E15)) | BK15: =IF(B15="","",IFERROR(INDEX(Settings!$G$5:$G$10,MATCH(BJ15,Settings!$F$5:$F$10,0)),Settings!$G$5)) | BL15: =IF(I15="","",IFERROR(1/(1/INDEX(Lists!$C$6:$C$17,MATCH(I15,Lists!$B$6:$B$17,0))),"")) | BM15: =IF(I15="","",IFERROR(1/(1/INDEX(Lists!$D$6:$D$17,MATCH(I15,Lists!$B$6:$B$17,0))),"")) | BN15: =IF(AN15="","",MAX(BK15,_xlfn.MAXIFS(AN$6:AN15,BJ$6:BJ15,BJ15))) | BO15: =IF(AN15="","",(AN15-BN15)/BN15) | BP15: =IF(OR(B15="",AL15=""),0,IF(OR(Settings!$C$28="All Accounts",BJ15=Settings!$C$28),1,0)) -> 0 | BQ15: =IF(BP15=1,SUM(BP$6:BP15),"") | BR15: =IF(BP15=1,ROUND(Settings!$C$29+SUMIFS(AM$6:AM15,BP$6:BP15,1),2),"") | BS15: =IF(BP15=1,MAX(Settings!$C$29,MAX(BR$6:BR15)),"") | BT15: =IF(BP15=1,(BR15-BS15)/BS15,"") | BU15: =IF(BP15=1,IF(AL15="Win",1+IF(BQ15=1,0,INDEX(BU$5:BU14,MATCH(BQ15-1,BQ$5:BQ14,0))),0),"") | BV15: =IF(BP15=1,IF(AL15="Loss",1+IF(BQ15=1,0,INDEX(BV$5:BV14,MATCH(BQ15-1,BQ$5:BQ14,0))),0),"")
A16: =IF(B16="","",ROW()-5) | C16: =IF(B16="","",CHOOSE(WEEKDAY(B16,2),"Mon","Tue","Wed","Thu","Fri","Sat","Sun")) | D16: =IF(B16="","",WEEKNUM(B16,2)) | X16: =IF(B16="","",COUNTIF(Q16:W16,"Yes")) | Y16: =IF(B16="","",IF(X16>=Settings!$C$16,"A+",IF(X16>=Settings!$C$17,"A",IF(X16>=Settings!$C$18,"B","C")))) | AI16: =IF(B16="","",ROUND(IF(AG16="",Settings!$C$5,AG16)*AW16,2)) | AJ16: =IF(OR(B16="",AB16="",AC16="",AD16=""),"",IFERROR(ROUND(ABS(AD16-AB16)/ABS(AB16-AC16),2),"")) | AK16: =IF(OR(B16="",AB16="",AC16="",AE16=""),"",IFERROR(ROUND(IF(J16="Short",AB16-AE16,AE16-AB16)/ABS(AB16-AC16),2),"")) | AL16: =IF(AK16="","",IF(ABS(AK16)<=Settings!$C$6,"BE",IF(AK16>0,"Win","Loss"))) | AM16: =IF(OR(AK16="",AI16=""),"",ROUND(AK16*AI16-N(AH16),2)) | AN16: =IF(AM16="","",ROUND(BK16+SUMIFS(AM$6:AM16,BJ$6:BJ16,BJ16),2)) | AO16: =IF(AK16="","",ROUND(SUMIFS(AK$6:AK16,BJ$6:BJ16,BJ16),2)) | AP16: =IF(OR(AK16="",BL16=""),"",IFERROR(ROUND(IF(J16="Short",AB16-AE16,AE16-AB16)/BL16,1),"")) | AQ16: =IF(OR(G16="",H16=""),"",ROUND(MOD(H16-G16,1)*1440,0)) | AR16: =IF(AQ16="","",IF(AQ16<15,"Under 15m",IF(AQ16<60,"15-60m",IF(AQ16<240,"1-4 hours","4+ hours")))) | AS16: =IF(G16="","",HOUR(G16)) | AT16: =IF(OR(Z16="",AB16="",BL16=""),"",IFERROR(ROUND(IF(J16="Short",Z16-AB16,AB16-Z16)/BL16,1),"")) | AU16: =IF(OR(AA16="",AC16=""),"",IF(AA16=AC16,"No","Yes")) | AV16: =IF(OR(B16="",BL16="",BM16="",AB16="",AC16=""),"",IFERROR(ROUND(AI16/(ABS(AB16-AC16)/BL16*BM16),2),"")) | AW16: =IF(B16="","",ROUND(BK16+SUMIFS(AM$5:AM15,BJ$5:BJ15,BJ16),2)) | AX16: =IF(B16="","",COUNTIFS(B$6:B16,B16,BJ$6:BJ16,BJ16)) | AY16: =IF(B16="","",ROUND(SUMIFS(AM$5:AM15,B$5:B15,B16,BJ$5:BJ15,BJ16),2)) | AZ16: =IF(AM16="","",ROUND(AY16+AM16,2)) | BA16: =IF(B16="","",ROUND(SUMIFS(AM$5:AM15,B$5:B15,">="&(B16-WEEKDAY(B16,2)+1),B$5:B15,"<="&B16,BJ$5:BJ15,BJ16),2)) | BB16: =IF(B16="","",IF(AND(AF16<>"",AV16<>"",N(AF16)>N(AV16)*(1+Settings!$C$13)),"Oversized",IF(AX16>Settings!$C$10,"Overtraded",IF(AY16<=-Settings!$C$11*(AW16-AY16),"Daily loss hit",IF(BA16<=-Settings!$C$12*(AW16-BA16),"Weekly loss hit","OK"))))) | BJ16: =IF(B16="","",IF(E16="",Settings!$F$5,E16)) | BK16: =IF(B16="","",IFERROR(INDEX(Settings!$G$5:$G$10,MATCH(BJ16,Settings!$F$5:$F$10,0)),Settings!$G$5)) | BL16: =IF(I16="","",IFERROR(1/(1/INDEX(Lists!$C$6:$C$17,MATCH(I16,Lists!$B$6:$B$17,0))),"")) | BM16: =IF(I16="","",IFERROR(1/(1/INDEX(Lists!$D$6:$D$17,MATCH(I16,Lists!$B$6:$B$17,0))),"")) | BN16: =IF(AN16="","",MAX(BK16,_xlfn.MAXIFS(AN$6:AN16,BJ$6:BJ16,BJ16))) | BO16: =IF(AN16="","",(AN16-BN16)/BN16) | BP16: =IF(OR(B16="",AL16=""),0,IF(OR(Settings!$C$28="All Accounts",BJ16=Settings!$C$28),1,0)) -> 0 | BQ16: =IF(BP16=1,SUM(BP$6:BP16),"") | BR16: =IF(BP16=1,ROUND(Settings!$C$29+SUMIFS(AM$6:AM16,BP$6:BP16,1),2),"") | BS16: =IF(BP16=1,MAX(Settings!$C$29,MAX(BR$6:BR16)),"") | BT16: =IF(BP16=1,(BR16-BS16)/BS16,"") | BU16: =IF(BP16=1,IF(AL16="Win",1+IF(BQ16=1,0,INDEX(BU$5:BU15,MATCH(BQ16-1,BQ$5:BQ15,0))),0),"") | BV16: =IF(BP16=1,IF(AL16="Loss",1+IF(BQ16=1,0,INDEX(BV$5:BV15,MATCH(BQ16-1,BQ$5:BQ15,0))),0),"")
A17: =IF(B17="","",ROW()-5) | C17: =IF(B17="","",CHOOSE(WEEKDAY(B17,2),"Mon","Tue","Wed","Thu","Fri","Sat","Sun")) | D17: =IF(B17="","",WEEKNUM(B17,2)) | X17: =IF(B17="","",COUNTIF(Q17:W17,"Yes")) | Y17: =IF(B17="","",IF(X17>=Settings!$C$16,"A+",IF(X17>=Settings!$C$17,"A",IF(X17>=Settings!$C$18,"B","C")))) | AI17: =IF(B17="","",ROUND(IF(AG17="",Settings!$C$5,AG17)*AW17,2)) | AJ17: =IF(OR(B17="",AB17="",AC17="",AD17=""),"",IFERROR(ROUND(ABS(AD17-AB17)/ABS(AB17-AC17),2),"")) | AK17: =IF(OR(B17="",AB17="",AC17="",AE17=""),"",IFERROR(ROUND(IF(J17="Short",AB17-AE17,AE17-AB17)/ABS(AB17-AC17),2),"")) | AL17: =IF(AK17="","",IF(ABS(AK17)<=Settings!$C$6,"BE",IF(AK17>0,"Win","Loss"))) | AM17: =IF(OR(AK17="",AI17=""),"",ROUND(AK17*AI17-N(AH17),2)) | AN17: =IF(AM17="","",ROUND(BK17+SUMIFS(AM$6:AM17,BJ$6:BJ17,BJ17),2)) | AO17: =IF(AK17="","",ROUND(SUMIFS(AK$6:AK17,BJ$6:BJ17,BJ17),2)) | AP17: =IF(OR(AK17="",BL17=""),"",IFERROR(ROUND(IF(J17="Short",AB17-AE17,AE17-AB17)/BL17,1),"")) | AQ17: =IF(OR(G17="",H17=""),"",ROUND(MOD(H17-G17,1)*1440,0)) | AR17: =IF(AQ17="","",IF(AQ17<15,"Under 15m",IF(AQ17<60,"15-60m",IF(AQ17<240,"1-4 hours","4+ hours")))) | AS17: =IF(G17="","",HOUR(G17)) | AT17: =IF(OR(Z17="",AB17="",BL17=""),"",IFERROR(ROUND(IF(J17="Short",Z17-AB17,AB17-Z17)/BL17,1),"")) | AU17: =IF(OR(AA17="",AC17=""),"",IF(AA17=AC17,"No","Yes")) | AV17: =IF(OR(B17="",BL17="",BM17="",AB17="",AC17=""),"",IFERROR(ROUND(AI17/(ABS(AB17-AC17)/BL17*BM17),2),"")) | AW17: =IF(B17="","",ROUND(BK17+SUMIFS(AM$5:AM16,BJ$5:BJ16,BJ17),2)) | AX17: =IF(B17="","",COUNTIFS(B$6:B17,B17,BJ$6:BJ17,BJ17)) | AY17: =IF(B17="","",ROUND(SUMIFS(AM$5:AM16,B$5:B16,B17,BJ$5:BJ16,BJ17),2)) | AZ17: =IF(AM17="","",ROUND(AY17+AM17,2)) | BA17: =IF(B17="","",ROUND(SUMIFS(AM$5:AM16,B$5:B16,">="&(B17-WEEKDAY(B17,2)+1),B$5:B16,"<="&B17,BJ$5:BJ16,BJ17),2)) | BB17: =IF(B17="","",IF(AND(AF17<>"",AV17<>"",N(AF17)>N(AV17)*(1+Settings!$C$13)),"Oversized",IF(AX17>Settings!$C$10,"Overtraded",IF(AY17<=-Settings!$C$11*(AW17-AY17),"Daily loss hit",IF(BA17<=-Settings!$C$12*(AW17-BA17),"Weekly loss hit","OK"))))) | BJ17: =IF(B17="","",IF(E17="",Settings!$F$5,E17)) | BK17: =IF(B17="","",IFERROR(INDEX(Settings!$G$5:$G$10,MATCH(BJ17,Settings!$F$5:$F$10,0)),Settings!$G$5)) | BL17: =IF(I17="","",IFERROR(1/(1/INDEX(Lists!$C$6:$C$17,MATCH(I17,Lists!$B$6:$B$17,0))),"")) | BM17: =IF(I17="","",IFERROR(1/(1/INDEX(Lists!$D$6:$D$17,MATCH(I17,Lists!$B$6:$B$17,0))),"")) | BN17: =IF(AN17="","",MAX(BK17,_xlfn.MAXIFS(AN$6:AN17,BJ$6:BJ17,BJ17))) | BO17: =IF(AN17="","",(AN17-BN17)/BN17) | BP17: =IF(OR(B17="",AL17=""),0,IF(OR(Settings!$C$28="All Accounts",BJ17=Settings!$C$28),1,0)) -> 0 | BQ17: =IF(BP17=1,SUM(BP$6:BP17),"") | BR17: =IF(BP17=1,ROUND(Settings!$C$29+SUMIFS(AM$6:AM17,BP$6:BP17,1),2),"") | BS17: =IF(BP17=1,MAX(Settings!$C$29,MAX(BR$6:BR17)),"") | BT17: =IF(BP17=1,(BR17-BS17)/BS17,"") | BU17: =IF(BP17=1,IF(AL17="Win",1+IF(BQ17=1,0,INDEX(BU$5:BU16,MATCH(BQ17-1,BQ$5:BQ16,0))),0),"") | BV17: =IF(BP17=1,IF(AL17="Loss",1+IF(BQ17=1,0,INDEX(BV$5:BV16,MATCH(BQ17-1,BQ$5:BQ16,0))),0),"")
A18: =IF(B18="","",ROW()-5) | C18: =IF(B18="","",CHOOSE(WEEKDAY(B18,2),"Mon","Tue","Wed","Thu","Fri","Sat","Sun")) | D18: =IF(B18="","",WEEKNUM(B18,2)) | X18: =IF(B18="","",COUNTIF(Q18:W18,"Yes")) | Y18: =IF(B18="","",IF(X18>=Settings!$C$16,"A+",IF(X18>=Settings!$C$17,"A",IF(X18>=Settings!$C$18,"B","C")))) | AI18: =IF(B18="","",ROUND(IF(AG18="",Settings!$C$5,AG18)*AW18,2)) | AJ18: =IF(OR(B18="",AB18="",AC18="",AD18=""),"",IFERROR(ROUND(ABS(AD18-AB18)/ABS(AB18-AC18),2),"")) | AK18: =IF(OR(B18="",AB18="",AC18="",AE18=""),"",IFERROR(ROUND(IF(J18="Short",AB18-AE18,AE18-AB18)/ABS(AB18-AC18),2),"")) | AL18: =IF(AK18="","",IF(ABS(AK18)<=Settings!$C$6,"BE",IF(AK18>0,"Win","Loss"))) | AM18: =IF(OR(AK18="",AI18=""),"",ROUND(AK18*AI18-N(AH18),2)) | AN18: =IF(AM18="","",ROUND(BK18+SUMIFS(AM$6:AM18,BJ$6:BJ18,BJ18),2)) | AO18: =IF(AK18="","",ROUND(SUMIFS(AK$6:AK18,BJ$6:BJ18,BJ18),2)) | AP18: =IF(OR(AK18="",BL18=""),"",IFERROR(ROUND(IF(J18="Short",AB18-AE18,AE18-AB18)/BL18,1),"")) | AQ18: =IF(OR(G18="",H18=""),"",ROUND(MOD(H18-G18,1)*1440,0)) | AR18: =IF(AQ18="","",IF(AQ18<15,"Under 15m",IF(AQ18<60,"15-60m",IF(AQ18<240,"1-4 hours","4+ hours")))) | AS18: =IF(G18="","",HOUR(G18)) | AT18: =IF(OR(Z18="",AB18="",BL18=""),"",IFERROR(ROUND(IF(J18="Short",Z18-AB18,AB18-Z18)/BL18,1),"")) | AU18: =IF(OR(AA18="",AC18=""),"",IF(AA18=AC18,"No","Yes")) | AV18: =IF(OR(B18="",BL18="",BM18="",AB18="",AC18=""),"",IFERROR(ROUND(AI18/(ABS(AB18-AC18)/BL18*BM18),2),"")) | AW18: =IF(B18="","",ROUND(BK18+SUMIFS(AM$5:AM17,BJ$5:BJ17,BJ18),2)) | AX18: =IF(B18="","",COUNTIFS(B$6:B18,B18,BJ$6:BJ18,BJ18)) | AY18: =IF(B18="","",ROUND(SUMIFS(AM$5:AM17,B$5:B17,B18,BJ$5:BJ17,BJ18),2)) | AZ18: =IF(AM18="","",ROUND(AY18+AM18,2)) | BA18: =IF(B18="","",ROUND(SUMIFS(AM$5:AM17,B$5:B17,">="&(B18-WEEKDAY(B18,2)+1),B$5:B17,"<="&B18,BJ$5:BJ17,BJ18),2)) | BB18: =IF(B18="","",IF(AND(AF18<>"",AV18<>"",N(AF18)>N(AV18)*(1+Settings!$C$13)),"Oversized",IF(AX18>Settings!$C$10,"Overtraded",IF(AY18<=-Settings!$C$11*(AW18-AY18),"Daily loss hit",IF(BA18<=-Settings!$C$12*(AW18-BA18),"Weekly loss hit","OK"))))) | BJ18: =IF(B18="","",IF(E18="",Settings!$F$5,E18)) | BK18: =IF(B18="","",IFERROR(INDEX(Settings!$G$5:$G$10,MATCH(BJ18,Settings!$F$5:$F$10,0)),Settings!$G$5)) | BL18: =IF(I18="","",IFERROR(1/(1/INDEX(Lists!$C$6:$C$17,MATCH(I18,Lists!$B$6:$B$17,0))),"")) | BM18: =IF(I18="","",IFERROR(1/(1/INDEX(Lists!$D$6:$D$17,MATCH(I18,Lists!$B$6:$B$17,0))),"")) | BN18: =IF(AN18="","",MAX(BK18,_xlfn.MAXIFS(AN$6:AN18,BJ$6:BJ18,BJ18))) | BO18: =IF(AN18="","",(AN18-BN18)/BN18) | BP18: =IF(OR(B18="",AL18=""),0,IF(OR(Settings!$C$28="All Accounts",BJ18=Settings!$C$28),1,0)) -> 0 | BQ18: =IF(BP18=1,SUM(BP$6:BP18),"") | BR18: =IF(BP18=1,ROUND(Settings!$C$29+SUMIFS(AM$6:AM18,BP$6:BP18,1),2),"") | BS18: =IF(BP18=1,MAX(Settings!$C$29,MAX(BR$6:BR18)),"") | BT18: =IF(BP18=1,(BR18-BS18)/BS18,"") | BU18: =IF(BP18=1,IF(AL18="Win",1+IF(BQ18=1,0,INDEX(BU$5:BU17,MATCH(BQ18-1,BQ$5:BQ17,0))),0),"") | BV18: =IF(BP18=1,IF(AL18="Loss",1+IF(BQ18=1,0,INDEX(BV$5:BV17,MATCH(BQ18-1,BQ$5:BQ17,0))),0),"")
... A505: =IF(B505="","",ROW()-5) | C505: =IF(B505="","",CHOOSE(WEEKDAY(B505,2),"Mon","Tue","Wed","Thu","Fri","Sat","Sun")) | D505: =IF(B505="","",WEEKNUM(B505,2)) | X505: =IF(B505="","",COUNTIF(Q505:W505,"Yes")) | Y505: =IF(B505="","",IF(X505>=Settings!$C$16,"A+",IF(X505>=Settings!$C$17,"A",IF(X505>=Settings!$C$18,"B","C")))) | AI505: =IF(B505="","",ROUND(IF(AG505="",Settings!$C$5,AG505)*AW505,2)) | AJ505: =IF(OR(B505="",AB505="",AC505="",AD505=""),"",IFERROR(ROUND(ABS(AD505-AB505)/ABS(AB505-AC505),2),"")) | AK505: =IF(OR(B505="",AB505="",AC505="",AE505=""),"",IFERROR(ROUND(IF(J505="Short",AB505-AE505,AE505-AB505)/ABS(AB505-AC505),2),"")) | AL505: =IF(AK505="","",IF(ABS(AK505)<=Settings!$C$6,"BE",IF(AK505>0,"Win","Loss"))) | AM505: =IF(OR(AK505="",AI505=""),"",ROUND(AK505*AI505-N(AH505),2)) | AN505: =IF(AM505="","",ROUND(BK505+SUMIFS(AM$6:AM505,BJ$6:BJ505,BJ505),2)) | AO505: =IF(AK505="","",ROUND(SUMIFS(AK$6:AK505,BJ$6:BJ505,BJ505),2)) | AP505: =IF(OR(AK505="",BL505=""),"",IFERROR(ROUND(IF(J505="Short",AB505-AE505,AE505-AB505)/BL505,1),"")) | AQ505: =IF(OR(G505="",H505=""),"",ROUND(MOD(H505-G505,1)*1440,0)) | AR505: =IF(AQ505="","",IF(AQ505<15,"Under 15m",IF(AQ505<60,"15-60m",IF(AQ505<240,"1-4 hours","4+ hours")))) | AS505: =IF(G505="","",HOUR(G505)) | AT505: =IF(OR(Z505="",AB505="",BL505=""),"",IFERROR(ROUND(IF(J505="Short",Z505-AB505,AB505-Z505)/BL505,1),"")) | AU505: =IF(OR(AA505="",AC505=""),"",IF(AA505=AC505,"No","Yes")) | AV505: =IF(OR(B505="",BL505="",BM505="",AB505="",AC505=""),"",IFERROR(ROUND(AI505/(ABS(AB505-AC505)/BL505*BM505),2),"")) | AW505: =IF(B505="","",ROUND(BK505+SUMIFS(AM$5:AM504,BJ$5:BJ504,BJ505),2)) | AX505: =IF(B505="","",COUNTIFS(B$6:B505,B505,BJ$6:BJ505,BJ505)) | AY505: =IF(B505="","",ROUND(SUMIFS(AM$5:AM504,B$5:B504,B505,BJ$5:BJ504,BJ505),2)) | AZ505: =IF(AM505="","",ROUND(AY505+AM505,2)) | BA505: =IF(B505="","",ROUND(SUMIFS(AM$5:AM504,B$5:B504,">="&(B505-WEEKDAY(B505,2)+1),B$5:B504,"<="&B505,BJ$5:BJ504,BJ505),2)) | BB505: =IF(B505="","",IF(AND(AF505<>"",AV505<>"",N(AF505)>N(AV505)*(1+Settings!$C$13)),"Oversized",IF(AX505>Settings!$C$10,"Overtraded",IF(AY505<=-Settings!$C$11*(AW505-AY505),"Daily loss hit",IF(BA505<=-Settings!$C$12*(AW505-BA505),"Weekly loss hit","OK"))))) | BJ505: =IF(B505="","",IF(E505="",Settings!$F$5,E505)) | BK505: =IF(B505="","",IFERROR(INDEX(Settings!$G$5:$G$10,MATCH(BJ505,Settings!$F$5:$F$10,0)),Settings!$G$5)) | BL505: =IF(I505="","",IFERROR(1/(1/INDEX(Lists!$C$6:$C$17,MATCH(I505,Lists!$B$6:$B$17,0))),"")) | BM505: =IF(I505="","",IFERROR(1/(1/INDEX(Lists!$D$6:$D$17,MATCH(I505,Lists!$B$6:$B$17,0))),"")) | BN505: =IF(AN505="","",MAX(BK505,_xlfn.MAXIFS(AN$6:AN505,BJ$6:BJ505,BJ505))) | BO505: =IF(AN505="","",(AN505-BN505)/BN505) | BP505: =IF(OR(B505="",AL505=""),0,IF(OR(Settings!$C$28="All Accounts",BJ505=Settings!$C$28),1,0)) -> 0 | BQ505: =IF(BP505=1,SUM(BP$6:BP505),"") | BR505: =IF(BP505=1,ROUND(Settings!$C$29+SUMIFS(AM$6:AM505,BP$6:BP505,1),2),"") | BS505: =IF(BP505=1,MAX(Settings!$C$29,MAX(BR$6:BR505)),"") | BT505: =IF(BP505=1,(BR505-BS505)/BS505,"") | BU505: =IF(BP505=1,IF(AL505="Win",1+IF(BQ505=1,0,INDEX(BU$5:BU504,MATCH(BQ505-1,BQ$5:BQ504,0))),0),"") | BV505: =IF(BP505=1,IF(AL505="Loss",1+IF(BQ505=1,0,INDEX(BV$5:BV504,MATCH(BQ505-1,BQ$5:BQ504,0))),0),"")

Sheet Daily Journal
B1: DAILY JOURNAL
B2: One row per trading day (weekdays from your Journal Start Date). Trades and P&L fill in automatically; type sleep, mood and notes in the blue cells.
B5: Date | C5: Day | D5: Trades | E5: Net P&L ($) | F5: Sleep (hrs) | G5: Mood | H5: Pre-market plan / bias | I5: End-of-day review
B6: =WORKDAY(Settings!$C$7-1,1) -> 46293 | C6: =CHOOSE(WEEKDAY(B6,2),"Mon","Tue","Wed","Thu","Fri","Sat","Sun") -> Mon | D6: =COUNTIFS(Journal!$B$6:$B$505,B6,Journal!$BP$6:$BP$505,1) -> 1 | E6: =SUMIFS(Journal!$AM$6:$AM$505,Journal!$B$6:$B$505,B6,Journal!$BP$6:$BP$505,1) -> 229.5
B7: =WORKDAY(B6,1) -> 46294 | C7: =CHOOSE(WEEKDAY(B7,2),"Mon","Tue","Wed","Thu","Fri","Sat","Sun") -> Tue | D7: =COUNTIFS(Journal!$B$6:$B$505,B7,Journal!$BP$6:$BP$505,1) -> 0 | E7: =SUMIFS(Journal!$AM$6:$AM$505,Journal!$B$6:$B$505,B7,Journal!$BP$6:$BP$505,1) -> 0
B8: =WORKDAY(B7,1) -> 46295 | C8: =CHOOSE(WEEKDAY(B8,2),"Mon","Tue","Wed","Thu","Fri","Sat","Sun") -> Wed | D8: =COUNTIFS(Journal!$B$6:$B$505,B8,Journal!$BP$6:$BP$505,1) -> 0 | E8: =SUMIFS(Journal!$AM$6:$AM$505,Journal!$B$6:$B$505,B8,Journal!$BP$6:$BP$505,1) -> 0
B9: =WORKDAY(B8,1) -> 46296 | C9: =CHOOSE(WEEKDAY(B9,2),"Mon","Tue","Wed","Thu","Fri","Sat","Sun") -> Thu | D9: =COUNTIFS(Journal!$B$6:$B$505,B9,Journal!$BP$6:$BP$505,1) -> 0 | E9: =SUMIFS(Journal!$AM$6:$AM$505,Journal!$B$6:$B$505,B9,Journal!$BP$6:$BP$505,1) -> 0
B10: =WORKDAY(B9,1) -> 46297 | C10: =CHOOSE(WEEKDAY(B10,2),"Mon","Tue","Wed","Thu","Fri","Sat","Sun") -> Fri | D10: =COUNTIFS(Journal!$B$6:$B$505,B10,Journal!$BP$6:$BP$505,1) -> 0 | E10: =SUMIFS(Journal!$AM$6:$AM$505,Journal!$B$6:$B$505,B10,Journal!$BP$6:$BP$505,1) -> 0
B11: =WORKDAY(B10,1) -> 46300 | C11: =CHOOSE(WEEKDAY(B11,2),"Mon","Tue","Wed","Thu","Fri","Sat","Sun") -> Mon | D11: =COUNTIFS(Journal!$B$6:$B$505,B11,Journal!$BP$6:$BP$505,1) -> 0 | E11: =SUMIFS(Journal!$AM$6:$AM$505,Journal!$B$6:$B$505,B11,Journal!$BP$6:$BP$505,1) -> 0
B12: =WORKDAY(B11,1) -> 46301 | C12: =CHOOSE(WEEKDAY(B12,2),"Mon","Tue","Wed","Thu","Fri","Sat","Sun") -> Tue | D12: =COUNTIFS(Journal!$B$6:$B$505,B12,Journal!$BP$6:$BP$505,1) -> 0 | E12: =SUMIFS(Journal!$AM$6:$AM$505,Journal!$B$6:$B$505,B12,Journal!$BP$6:$BP$505,1) -> 0
B13: =WORKDAY(B12,1) -> 46302 | C13: =CHOOSE(WEEKDAY(B13,2),"Mon","Tue","Wed","Thu","Fri","Sat","Sun") -> Wed | D13: =COUNTIFS(Journal!$B$6:$B$505,B13,Journal!$BP$6:$BP$505,1) -> 0 | E13: =SUMIFS(Journal!$AM$6:$AM$505,Journal!$B$6:$B$505,B13,Journal!$BP$6:$BP$505,1) -> 0
B14: =WORKDAY(B13,1) -> 46303 | C14: =CHOOSE(WEEKDAY(B14,2),"Mon","Tue","Wed","Thu","Fri","Sat","Sun") -> Thu | D14: =COUNTIFS(Journal!$B$6:$B$505,B14,Journal!$BP$6:$BP$505,1) -> 0 | E14: =SUMIFS(Journal!$AM$6:$AM$505,Journal!$B$6:$B$505,B14,Journal!$BP$6:$BP$505,1) -> 0
B15: =WORKDAY(B14,1) -> 46304 | C15: =CHOOSE(WEEKDAY(B15,2),"Mon","Tue","Wed","Thu","Fri","Sat","Sun") -> Fri | D15: =COUNTIFS(Journal!$B$6:$B$505,B15,Journal!$BP$6:$BP$505,1) -> 0 | E15: =SUMIFS(Journal!$AM$6:$AM$505,Journal!$B$6:$B$505,B15,Journal!$BP$6:$BP$505,1) -> 0
B16: =WORKDAY(B15,1) -> 46307 | C16: =CHOOSE(WEEKDAY(B16,2),"Mon","Tue","Wed","Thu","Fri","Sat","Sun") -> Mon | D16: =COUNTIFS(Journal!$B$6:$B$505,B16,Journal!$BP$6:$BP$505,1) -> 0 | E16: =SUMIFS(Journal!$AM$6:$AM$505,Journal!$B$6:$B$505,B16,Journal!$BP$6:$BP$505,1) -> 0
B17: =WORKDAY(B16,1) -> 46308 | C17: =CHOOSE(WEEKDAY(B17,2),"Mon","Tue","Wed","Thu","Fri","Sat","Sun") -> Tue | D17: =COUNTIFS(Journal!$B$6:$B$505,B17,Journal!$BP$6:$BP$505,1) -> 0 | E17: =SUMIFS(Journal!$AM$6:$AM$505,Journal!$B$6:$B$505,B17,Journal!$BP$6:$BP$505,1) -> 0
B18: =WORKDAY(B17,1) -> 46309 | C18: =CHOOSE(WEEKDAY(B18,2),"Mon","Tue","Wed","Thu","Fri","Sat","Sun") -> Wed | D18: =COUNTIFS(Journal!$B$6:$B$505,B18,Journal!$BP$6:$BP$505,1) -> 0 | E18: =SUMIFS(Journal!$AM$6:$AM$505,Journal!$B$6:$B$505,B18,Journal!$BP$6:$BP$505,1) -> 0
... B135: =WORKDAY(B134,1) -> 46472 | C135: =CHOOSE(WEEKDAY(B135,2),"Mon","Tue","Wed","Thu","Fri","Sat","Sun") -> Fri | D135: =COUNTIFS(Journal!$B$6:$B$505,B135,Journal!$BP$6:$BP$505,1) -> 0 | E135: =SUMIFS(Journal!$AM$6:$AM$505,Journal!$B$6:$B$505,B135,Journal!$BP$6:$BP$505,1) -> 0

Sheet Analytics
B1: ANALYTICS
B2: Every table follows the Account View chosen on the Dashboard (except the Account table). Green = profit, red = loss.
B5: Session - performance by trading session | M5: JUMP TO
B6: Session | C6: Trades | D6: Wins | E6: Losses | F6: BE | G6: Win % | H6: Total R | I6: Avg R | J6: Net P&L ($) | K6: Profit Factor | M6: Session
B7: =IF(Lists!$F$6="","",Lists!$F$6) -> Asia | C7: =IF($B7="","",D7+E7+F7) -> 0 | D7: =IF($B7="","",COUNTIFS(Journal!$F$6:$F$505,$B7,Journal!$AL$6:$AL$505,"Win",Journal!$BP$6:$BP$505,1)) -> 0 | E7: =IF($B7="","",COUNTIFS(Journal!$F$6:$F$505,$B7,Journal!$AL$6:$AL$505,"Loss",Journal!$BP$6:$BP$505,1)) -> 0 | F7: =IF($B7="","",COUNTIFS(Journal!$F$6:$F$505,$B7,Journal!$AL$6:$AL$505,"BE",Journal!$BP$6:$BP$505,1)) -> 0 | G7: =IF($B7="","",IFERROR(D7/C7,0)) -> 0 | H7: =IF($B7="","",SUMIFS(Journal!$AK$6:$AK$505,Journal!$F$6:$F$505,$B7,Journal!$BP$6:$BP$505,1)) -> 0 | I7: =IF($B7="","",IFERROR(H7/C7,0)) -> 0 | J7: =IF($B7="","",SUMIFS(Journal!$AM$6:$AM$505,Journal!$F$6:$F$505,$B7,Journal!$BP$6:$BP$505,1)) -> 0 | K7: =IF($B7="","",IFERROR(SUMIFS(Journal!$AM$6:$AM$505,Journal!$F$6:$F$505,$B7,Journal!$BP$6:$BP$505,1,Journal!$AM$6:$AM$505,">0")/ABS(SUMIFS(Journal!$AM$6:$AM$505,Journal!$F$6:$F$505,$B7,Journal!$BP$6:$BP$505,1,Journal!$AM$6:$AM$505,"<0")),"-")) -> - | M7: Pair
B8: =IF(Lists!$F$7="","",Lists!$F$7) -> London | C8: =IF($B8="","",D8+E8+F8) -> 1 | D8: =IF($B8="","",COUNTIFS(Journal!$F$6:$F$505,$B8,Journal!$AL$6:$AL$505,"Win",Journal!$BP$6:$BP$505,1)) -> 1 | E8: =IF($B8="","",COUNTIFS(Journal!$F$6:$F$505,$B8,Journal!$AL$6:$AL$505,"Loss",Journal!$BP$6:$BP$505,1)) -> 0 | F8: =IF($B8="","",COUNTIFS(Journal!$F$6:$F$505,$B8,Journal!$AL$6:$AL$505,"BE",Journal!$BP$6:$BP$505,1)) -> 0 | G8: =IF($B8="","",IFERROR(D8/C8,0)) -> 1 | H8: =IF($B8="","",SUMIFS(Journal!$AK$6:$AK$505,Journal!$F$6:$F$505,$B8,Journal!$BP$6:$BP$505,1)) -> 2.33 | I8: =IF($B8="","",IFERROR(H8/C8,0)) -> 2.33 | J8: =IF($B8="","",SUMIFS(Journal!$AM$6:$AM$505,Journal!$F$6:$F$505,$B8,Journal!$BP$6:$BP$505,1)) -> 229.5 | K8: =IF($B8="","",IFERROR(SUMIFS(Journal!$AM$6:$AM$505,Journal!$F$6:$F$505,$B8,Journal!$BP$6:$BP$505,1,Journal!$AM$6:$AM$505,">0")/ABS(SUMIFS(Journal!$AM$6:$AM$505,Journal!$F$6:$F$505,$B8,Journal!$BP$6:$BP$505,1,Journal!$AM$6:$AM$505,"<0")),"-")) -> - | M8: Setup / Model
